Workbook
Name HandleListWithPiston: '[1]#REF'!$F$11:$G$26
Name HandleListWithPiston2: '[1]#REF'!$F$11:$F$26

Sheet SELL 
A1: Sell List
A3: TEL: FAX: E:
A4: Name: | F4: Date: | K4: Phone:
A5: Fax: | F5: Address: | K5: Product Code
A6: Product | B6: Qty | C6: Price | D6: TOTAL | F6: Product | G6: Qty | H6: Price | I6: TOTAL
A7: F9-W3036 | B7: 1 | C7: =IFERROR(VLOOKUP(A7,PRICE!$A$1:$B$2601,2,FALSE),"0") -> 851 | D7: =C7*B7 -> 851 | F7: F9-DB30 | G7: 1 | H7: =IFERROR(VLOOKUP(F7,PRICE!$A$1:$B$2601,2,FALSE),"0") -> 1490 | I7: =H7*G7 -> 1490
A8: F9-W4236 | B8: 1 | C8: =IFERROR(VLOOKUP(A8,PRICE!$A$1:$B$2601,2,FALSE),"0") -> 1200 | D8: =C8*B8 -> 1200 | F8: F9-DB24 | G8: 1 | H8: =IFERROR(VLOOKUP(F8,PRICE!$A$1:$B$2601,2,FALSE),"0") -> 1346 | I8: =H8*G8 -> 1346
A9: F9-WEP1336 | B9: 4 | C9: =IFERROR(VLOOKUP(A9,PRICE!$A$1:$B$2601,2,FALSE),"0") -> 51 | D9: =C9*B9 -> 204 | F9: F9-FB36 | G9: 1 | H9: =IFERROR(VLOOKUP(F9,PRICE!$A$1:$B$2601,2,FALSE),"0") -> 1046 | I9: =H9*G9 -> 1046
A10: F9-WF396 | B10: 3 | C10: =IFERROR(VLOOKUP(A10,PRICE!$A$1:$B$2601,2,FALSE),"0") -> 133 | D10: =C10*B10 -> 399 | G10: 1 | H10: =IFERROR(VLOOKUP(F10,PRICE!$A$1:$B$2601,2,FALSE),"0") -> 0 | I10: =H10*G10 -> 0 | K10: Instructions
A11: F9-WF1.596 | B11: 2 | C11: =IFERROR(VLOOKUP(A11,PRICE!$A$1:$B$2601,2,FALSE),"0") -> 83 | D11: =C11*B11 -> 166 | F11: F9-B18-PO | G11: 1 | H11: =IFERROR(VLOOKUP(F11,PRICE!$A$1:$B$2601,2,FALSE),"0") -> 1060 | I11: =H11*G11 -> 1060 | K11: 1. Select product from drop-down menu of column 1 and 2
B12: 1 | C12: =IFERROR(VLOOKUP(A12,PRICE!$A$1:$B$2601,2,FALSE),"0") -> 0 | D12: =C12*B12 -> 0 | F12: F9-Garbage Bin | G12: 2 | H12: =IFERROR(VLOOKUP(F12,PRICE!$A$1:$B$2601,2,FALSE),"0") -> 37 | I12: =H12*G12 -> 74
B13: 1 | C13: =IFERROR(VLOOKUP(A13,PRICE!$A$1:$B$2601,2,FALSE),"0") -> 0 | D13: =C13*B13 -> 0 | F13: F9-DB36 | G13: 1 | H13: =IFERROR(VLOOKUP(F13,PRICE!$A$1:$B$2601,2,FALSE),"0") -> 1620 | I13: =H13*G13 -> 1620 | K13: 2. Enter quantity
B14: 1 | C14: =IFERROR(VLOOKUP(A14,PRICE!$A$1:$B$2601,2,FALSE),"0") -> 0 | D14: =C14*B14 -> 0 | F14: F9-FB42 | G14: 1 | H14: =IFERROR(VLOOKUP(F14,PRICE!$A$1:$B$2601,2,FALSE),"0") -> 1140 | I14: =H14*G14 -> 1140 | K14: 3. Enter discount rate at the bottom
B15: 1 | C15: =IFERROR(VLOOKUP(A15,PRICE!$A$1:$B$2601,2,FALSE),"0") -> 0 | D15: =C15*B15 -> 0 | F15: F9-W3330 | G15: 2 | H15: =IFERROR(VLOOKUP(F15,PRICE!$A$1:$B$2601,2,FALSE),"0") -> 794 | I15: =H15*G15 -> 1588 | K15: 4. Enter tax rate at the bottom
B16: 5 | C16: =IFERROR(VLOOKUP(A16,PRICE!$A$1:$B$2601,2,FALSE),"0") -> 0 | D16: =C16*B16 -> 0 | F16: F9-W3030 | G16: 1 | H16: =IFERROR(VLOOKUP(F16,PRICE!$A$1:$B$2601,2,FALSE),"0") -> 727 | I16: =H16*G16 -> 727 | K16: *Please refer to "Price List & Description" tab at bottom for details
B17: 2 | C17: =IFERROR(VLOOKUP(A17,PRICE!$A$1:$B$2601,2,FALSE),"0") -> 0 | D17: =C17*B17 -> 0 | F17: F9-ISP37.75X36 | G17: 2 | H17: =IFERROR(VLOOKUP(F17,PRICE!$A$1:$B$2601,2,FALSE),"0") -> 175 | I17: =H17*G17 -> 350
B18: 2 | C18: =IFERROR(VLOOKUP(A18,PRICE!$A$1:$B$2601,2,FALSE),"0") -> 0 | D18: =C18*B18 -> 0 | F18: F9-TK8 | G18: 4 | H18: =IFERROR(VLOOKUP(F18,PRICE!$A$1:$B$2601,2,FALSE),"0") -> 47 | I18: =H18*G18 -> 188
B19: 3 | C19: =IFERROR(VLOOKUP(A19,PRICE!$A$1:$B$2601,2,FALSE),"0") -> 0 | D19: =C19*B19 -> 0 | F19: F9-WF330 | G19: 3 | H19: =IFERROR(VLOOKUP(F19,PRICE!$A$1:$B$2601,2,FALSE),"0") -> 47 | I19: =H19*G19 -> 141
B20: 1 | C20: =IFERROR(VLOOKUP(A20,PRICE!$A$1:$B$2601,2,FALSE),"0") -> 0 | D20: =C20*B20 -> 0 | G20: 4 | H20: =IFERROR(VLOOKUP(F20,PRICE!$A$1:$B$2601,2,FALSE),"0") -> 0 | I20: =H20*G20 -> 0
B21: 3 | C21: =IFERROR(VLOOKUP(A21,PRICE!$A$1:$B$2601,2,FALSE),"0") -> 0 | D21: =C21*B21 -> 0 | H21: =IFERROR(VLOOKUP(F21,PRICE!$A$1:$B$2601,2,FALSE),"0") -> 0 | I21: =H21*G21 -> 0 | K21: Assembly Cost
C22: =IFERROR(VLOOKUP(A22,PRICE!$A$1:$B$2601,2,FALSE),"0") -> 0 | D22: =C22*B22 -> 0 | H22: =IFERROR(VLOOKUP(F22,PRICE!$A$1:$B$2601,2,FALSE),"0") -> 0 | I22: =H22*G22 -> 0
C23: =IFERROR(VLOOKUP(A23,PRICE!$A$1:$B$2601,2,FALSE),"0") -> 0 | D23: =C23*B23 -> 0 | H23: =IFERROR(VLOOKUP(F23,PRICE!$A$1:$B$2601,2,FALSE),"0") -> 0 | I23: =H23*G23 -> 0 | K23: Assembly Type | L23: Quantity | M23: per unit
C24: =IFERROR(VLOOKUP(A24,PRICE!$A$1:$B$2601,2,FALSE),"0") -> 0 | D24: =C24*B24 -> 0 | H24: =IFERROR(VLOOKUP(F24,PRICE!$A$1:$B$2601,2,FALSE),"0") -> 0 | I24: =H24*G24 -> 0 | K24: Base Units | L24: 6 | M24: 50
C25: =IFERROR(VLOOKUP(A25,PRICE!$A$1:$B$2601,2,FALSE),"0") -> 0 | D25: =C25*B25 -> 0 | H25: =IFERROR(VLOOKUP(F25,PRICE!$A$1:$B$2601,2,FALSE),"0") -> 0 | I25: =H25*G25 -> 0 | K25: Wall Units | L25: 5 | M25: 25
C26: =IFERROR(VLOOKUP(A26,PRICE!$A$1:$B$2601,2,FALSE),"0") -> 0 | D26: =C26*B26 -> 0 | H26: =IFERROR(VLOOKUP(F26,PRICE!$A$1:$B$2601,2,FALSE),"0") -> 0 | I26: =H26*G26 -> 0 | K26: Tall Panty, Lazy Susan, Mantle and 48"-60" Vanity units | M26: 100
C27: =IFERROR(VLOOKUP(A27,PRICE!$A$1:$B$2601,2,FALSE),"0") -> 0 | D27: =C27*B27 -> 0 | H27: =IFERROR(VLOOKUP(F27,PRICE!$A$1:$B$2601,2,FALSE),"0") -> 0 | I27: =H27*G27 -> 0
C28: =IFERROR(VLOOKUP(A28,PRICE!$A$1:$B$2601,2,FALSE),"0") -> 0 | D28: =C28*B28 -> 0 | H28: =IFERROR(VLOOKUP(F28,PRICE!$A$1:$B$2601,2,FALSE),"0") -> 0 | I28: =H28*G28 -> 0 | K28: Custom Assembly Costs:
C29: =IFERROR(VLOOKUP(A29,PRICE!$A$1:$B$2601,2,FALSE),"0") -> 0 | D29: =C29*B29 -> 0 | H29: =IFERROR(VLOOKUP(F29,PRICE!$A$1:$B$2601,2,FALSE),"0") -> 0 | I29: =H29*G29 -> 0 | K29: Delivery Costs:
A30: handles | B30: Qty | C30: Price | D30: TOTAL | F30: Custom items | G30: Qty | H30: Price | I30: TOTAL | K30: Total Cost: | L30: =(L24*M24)+(L25*M25)+(L26*M26)+L28+L29 -> 425
D31: =C31*B31 -> 0
D32: =C32*B32 -> 0
D33: =C33*B33 -> 0
D34: =C34*B34 -> 0
D35: =C35*B35 -> 0 | I35: =H35*G35 -> 0
A36: List Total: | C36: =SUM(D7:D29)+SUM(I7:I29) -> 13590 | F36: Discount Rate: | H36: 0.76 | K36: After Disc: | M36: =(C36+M30)*(1-H36) -> 3261.6
A37: Assembly Cost: | C37: =L30 -> 425 | F37: Subtotal: | H37: =M36+C37+SUM(D31:D35)+SUM(I31:I35) -> 3686.6 | K37: QST+GST (%): | L37: 0.09975 | M37: 0.05
A38: GST: | B38: =H37*M37 -> 184.33 | C38: QST: | D38: =H37*L37 -> 367.73835 | F38: TOTAL GST+QST | H38: =D38+B38 -> 552.06835 | K38: Total: | M38: =H37+H38 -> 4238.6683

Sheet PRICE
A1: 型号 | B1: 零售价
A2: MUF9-B12 | B2: 810 | C2: F9-B12 | D2: 742 | E2: =B2-D2 -> 68 | F2: =E2/B2 -> 0.083950617
A3: MUF9-B15 | B3: 900 | C3: F9-B15 | D3: 822 | E3: =B3-D3 -> 78 | F3: =E3/B3 -> 0.086666667 | I3: muf9
A4: MUF9-B18 | B4: 970 | C4: F9-B18 | D4: 883 | E4: =B4-D4 -> 87 | F4: =E4/B4 -> 0.089690722 | I4: 1pouce shaker
A5: MUF9-B18-PO | B5: 1171 | C5: F9-B18-PO | D5: 1060 | E5: =B5-D5 -> 111 | F5: =E5/B5 -> 0.094790777
A6: MUF9-B21 | B6: 1017 | C6: F9-B21 | D6: 925 | E6: =B6-D6 -> 92 | F6: =E6/B6 -> 0.090462144
A7: MUF9-BBC42 | B7: 1336 | C7: F9-BBC42 | D7: 1203 | E7: =B7-D7 -> 133 | F7: =E7/B7 -> 0.099550898 | I7: f8
A8: MUF9-BBC45 | B8: 1457 | C8: F9-BBC45 | D8: 1303 | E8: =B8-D8 -> 154 | F8: =E8/B8 -> 0.10569664
A9: MUF9-BBC48 | B9: 1569 | C9: F9-BBC48 | D9: 1404 | E9: =B9-D9 -> 165 | F9: =E9/B9 -> 0.10516252
A10: MUF9-BMC27 | B10: 1393 | C10: F9-BMC27 | D10: 1241 | E10: =B10-D10 -> 152 | F10: =E10/B10 -> 0.10911701
A11: MUF9-DB12 | B11: 1153 | C11: F9-DB12 | D11: 1059 | E11: =B11-D11 -> 94 | F11: =E11/B11 -> 0.081526453
A12: MUF9-DB15 | B12: 1273 | C12: F9-DB15 | D12: 1157 | E12: =B12-D12 -> 116 | F12: =E12/B12 -> 0.091123331
A13: MUF9-DB18 | B13: 1364 | C13: F9-DB18 | D13: 1202 | E13: =B13-D13 -> 162 | F13: =E13/B13 -> 0.11876833
A14: MUF9-DB21 | B14: 1467 | C14: F9-DB21 | D14: 1306 | E14: =B14-D14 -> 161 | F14: =E14/B14 -> 0.10974778
A15: MUF9-DB24 | B15: 1509 | C15: F9-DB24 | D15: 1346 | E15: =B15-D15 -> 163 | F15: =E15/B15 -> 0.10801856
A16: MUF9-DB27 | B16: 1597 | C16: F9-DB27 | D16: 1419 | E16: =B16-D16 -> 178 | F16: =E16/B16 -> 0.11145899
A17: MUF9-DB30 | B17: 1669 | C17: F9-DB30 | D17: 1490 | E17: =B17-D17 -> 179 | F17: =E17/B17 -> 0.10724985
A18: MUF9-DB33 | B18: 1754 | C18: F9-DB33 | D18: 1552 | E18: =B18-D18 -> 202 | F18: =E18/B18 -> 0.11516534
A19: MUF9-DB36 | B19: 1854 | C19: F9-DB36 | D19: 1620 | E19: =B19-D19 -> 234 | F19: =E19/B19 -> 0.12621359
A20: MUF9-DB12-2 | B20: 865
A21: MUF9-DB15-2 | B21: 944
A22: MUF9-DB18-2 | B22: 1030
A23: MUF9-DB21-2 | B23: 1139
A24: MUF9-DB24-2 | B24: 1239
A25: MUF9-DB27-2 | B25: 1328 | C25: F9-DB27-2 | D25: 1122 | E25: =B25-D25 -> 206 | F25: =E25/B25 -> 0.15512048
A26: MUF9-DB30-2 | B26: 1419 | C26: F9-DB30-2 | D26: 1211 | E26: =B26-D26 -> 208 | F26: =E26/B26 -> 0.1465821
A27: MUF9-DB33-2 | B27: 1519
A28: MUF9-DB36-2 | B28: 1621
A29: MUF9-FB09 | B29: 535 | C29: F9-FB09 | D29: 492 | E29: =B29-D29 -> 43 | F29: =E29/B29 -> 0.080373832
A30: MUF9-FB12 | B30: 598 | C30: F9-FB12 | D30: 545 | E30: =B30-D30 -> 53 | F30: =E30/B30 -> 0.088628763
A31: MUF9-FB15 | B31: 676 | C31: F9-FB15 | D31: 616 | E31: =B31-D31 -> 60 | F31: =E31/B31 -> 0.088757396
A32: MUF9-FB18 | B32: 740 | C32: F9-FB18 | D32: 670 | E32: =B32-D32 -> 70 | F32: =E32/B32 -> 0.094594595
A33: MUF9-FB21 | B33: 818 | C33: F9-FB21 | D33: 732 | E33: =B33-D33 -> 86 | F33: =E33/B33 -> 0.10513447
A34: MUF9-FB24 | B34: 911 | C34: F9-FB24 | D34: 817 | E34: =B34-D34 -> 94 | F34: =E34/B34 -> 0.10318332
A35: MUF9-FB27 | B35: 982 | C35: F9-FB27 | D35: 875 | E35: =B35-D35 -> 107 | F35: =E35/B35 -> 0.1089613
A36: MUF9-FB30 | B36: 1051 | C36: F9-FB30 | D36: 937 | E36: =B36-D36 -> 114 | F36: =E36/B36 -> 0.10846813
A37: MUF9-FB33 | B37: 1110 | C37: F9-FB33 | D37: 991 | E37: =B37-D37 -> 119 | F37: =E37/B37 -> 0.10720721
A38: MUF9-FB36 | B38: 1187 | C38: F9-FB36 | D38: 1046 | E38: =B38-D38 -> 141 | F38: =E38/B38 -> 0.11878686
A39: MUF9-FB39 | B39: 1266 | C39: F9-FB39 | D39: 1109 | E39: =B39-D39 -> 157 | F39: =E39/B39 -> 0.12401264
A40: MUF9-FB42 | B40: 1301 | C40: F9-FB42 | D40: 1140 | E40: =B40-D40 -> 161 | F40: =E40/B40 -> 0.12375096
...

Sheet price bc
A1: Product Code Yihai | B1: Price Yihai | C1: Price Dilamco - Standard | D1: Price Dilamco - Chene Blanc | E1: Product | F1: Product Type | G1: Product Sub-type | H1: Part Type | I1: Certain? Catégorie | J1: Certain Item | K1: Width | L1: Height | M1: Depth | N1: Door | O1: Drawer
A2: F9-Garbage Bin | B2: 37 | C2: =B2*0.3 -> 11.1 | E2: =_xlfn.TEXTAFTER(A2,"-") -> Garbage Bin | F2: {=_xlfn.LET( _xlpm.p,E2, _xlpm.code,IFERROR( IF(AND(LEFT(_xlpm.p,2)="DB",ISNUMBER(SEARCH("-2",_xlpm.p))),"DB-2", IF(LEFT(_xlpm.p,3)="OC-","OC", LEFT(_xlpm.p,_xlfn.XMATCH(TRUE,ISNUMBER(--MID(_xlpm.p,_xlfn.SEQUENCE(LEN(_xlpm.p)),1)))-1) ) ), _xlpm.p ), _xlfn.XLOOKUP(_xlpm.code,'Product Code'!A:A,'Product Code'!B:B,"") )} -> Accessories | G2: {=_xlfn.LET( _xlpm.p,E2, _xlpm.code,IFERROR( IF(AND(LEFT(_xlpm.p,2)="DB",ISNUMBER(SEARCH("-2",_xlpm.p))),"DB-2", IF(LEFT(_xlpm.p,3)="OC-","OC", LEFT(_xlpm.p,_xlfn.XMATCH(TRUE,ISNUMBER(--MID(_xlpm.p,_xlfn.SEQUENCE(LEN(_xlpm.p)),1)))-1) ) ), _xlpm.p ), _xlpm.base,_xlfn.XLOOKUP(_xlpm.code,'Product Code'!A:A,'Product Code'!C:C,""), IF(RIGHT(_xlpm.p,3)="-PO",_xlpm.base&" - Pull-Out",_xlpm.base) )} -> Plastic Garbage Bin | H2: N/A | I2: {=_xlfn.LET( _xlpm.p,E2, _xlpm.code,IFERROR( IF(AND(LEFT(_xlpm.p,2)="DB",ISNUMBER(SEARCH("-2",_xlpm.p))),"DB-2", IF(LEFT(_xlpm.p,3)="OC-","OC", LEFT(_xlpm.p,_xlfn.XMATCH(TRUE,ISNUMBER(--MID(_xlpm.p,_xlfn.SEQUENCE(LEN(_xlpm.p)),1)))-1) ) ), _xlpm.p ), _xlpm.productType,_xlfn.XLOOKUP(_xlpm.code,'Product Code'!A:A,'Product Code'!D:D,""), IF(OR(RIGHT(_xlpm.p,5)="-Door",RIGHT(_xlpm.p,6)="-DOORS"),_xlpm.productType&" - Door",_xlpm.productType) )} -> 0 | K2: N/A | L2: N/A | M2: N/A | N2: 1 | O2: 1
A3: F9-美式铰链 | B3: 10 | C3: =B3*0.3 -> 3 | E3: =_xlfn.TEXTAFTER(A3,"-") -> 美式铰链 | F3: {=_xlfn.LET( _xlpm.p,E3, _xlpm.code,IFERROR( IF(AND(LEFT(_xlpm.p,2)="DB",ISNUMBER(SEARCH("-2",_xlpm.p))),"DB-2", IF(LEFT(_xlpm.p,3)="OC-","OC", LEFT(_xlpm.p,_xlfn.XMATCH(TRUE,ISNUMBER(--MID(_xlpm.p,_xlfn.SEQUENCE(LEN(_xlpm.p)),1)))-1) ) ), _xlpm.p ), _xlfn.XLOOKUP(_xlpm.code,'Product Code'!A:A,'Product Code'!B:B,"") )} -> American Style Hinge | G3: {=_xlfn.LET( _xlpm.p,E3, _xlpm.code,IFERROR( IF(AND(LEFT(_xlpm.p,2)="DB",ISNUMBER(SEARCH("-2",_xlpm.p))),"DB-2", IF(LEFT(_xlpm.p,3)="OC-","OC", LEFT(_xlpm.p,_xlfn.XMATCH(TRUE,ISNUMBER(--MID(_xlpm.p,_xlfn.SEQUENCE(LEN(_xlpm.p)),1)))-1) ) ), _xlpm.p ), _xlpm.base,_xlfn.XLOOKUP(_xlpm.code,'Product Code'!A:A,'Product Code'!C:C,""), IF(RIGHT(_xlpm.p,3)="-PO",_xlpm.base&" - Pull-Out",_xlpm.base) )} -> 0 | I3: {=_xlfn.LET( _xlpm.p,E3, _xlpm.code,IFERROR( IF(AND(LEFT(_xlpm.p,2)="DB",ISNUMBER(SEARCH("-2",_xlpm.p))),"DB-2", IF(LEFT(_xlpm.p,3)="OC-","OC", LEFT(_xlpm.p,_xlfn.XMATCH(TRUE,ISNUMBER(--MID(_xlpm.p,_xlfn.SEQUENCE(LEN(_xlpm.p)),1)))-1) ) ), _xlpm.p ), _xlpm.productType,_xlfn.XLOOKUP(_xlpm.code,'Product Code'!A:A,'Product Code'!D:D,""), IF(OR(RIGHT(_xlpm.p,5)="-Door",RIGHT(_xlpm.p,6)="-DOORS"),_xlpm.productType&" - Door",_xlpm.productType) )} -> - | N3: 1 | O3: 1
A4: F9-B12 | B4: 742 | C4: =B4*0.3 -> 222.6 | D4: =C4*1.13 -> 251.538 | E4: =_xlfn.TEXTAFTER(A4,"-") -> B12 | F4: {=_xlfn.LET( _xlpm.p,E4, _xlpm.code,IFERROR( IF(AND(LEFT(_xlpm.p,2)="DB",ISNUMBER(SEARCH("-2",_xlpm.p))),"DB-2", IF(LEFT(_xlpm.p,3)="OC-","OC", LEFT(_xlpm.p,_xlfn.XMATCH(TRUE,ISNUMBER(--MID(_xlpm.p,_xlfn.SEQUENCE(LEN(_xlpm.p)),1)))-1) ) ), _xlpm.p ), _xlpm.productType,_xlfn.XLOOKUP(_xlpm.code,'Product Code'!A:A,'Product Code'!B:B,""), IF(OR(RIGHT(_xlpm.p,5)="-Door",RIGHT(_xlpm.p,6)="-DOORS"),_xlpm.productType&" - Door",_xlpm.productType) )} -> Base Cabinet | G4: {=_xlfn.LET( _xlpm.p,E4, _xlpm.code,IFERROR( IF(AND(LEFT(_xlpm.p,2)="DB",ISNUMBER(SEARCH("-2",_xlpm.p))),"DB-2", IF(LEFT(_xlpm.p,3)="OC-","OC", LEFT(_xlpm.p,_xlfn.XMATCH(TRUE,ISNUMBER(--MID(_xlpm.p,_xlfn.SEQUENCE(LEN(_xlpm.p)),1)))-1) ) ), _xlpm.p ), _xlpm.base,_xlfn.XLOOKUP(_xlpm.code,'Product Code'!A:A,'Product Code'!C:C,""), IF(RIGHT(_xlpm.p,3)="-PO",_xlpm.base&" - Pull-Out",_xlpm.base) )} -> Standard | H4: Complete Cabinet | I4: {=_xlfn.LET( _xlpm.p,E4, _xlpm.code,IFERROR( IF(AND(LEFT(_xlpm.p,2)="DB",ISNUMBER(SEARCH("-2",_xlpm.p))),"DB-2", IF(LEFT(_xlpm.p,3)="OC-","OC", LEFT(_xlpm.p,_xlfn.XMATCH(TRUE,ISNUMBER(--MID(_xlpm.p,_xlfn.SEQUENCE(LEN(_xlpm.p)),1)))-1) ) ), _xlpm.p ), _xlpm.productType,_xlfn.XLOOKUP(_xlpm.code,'Product Code'!A:A,'Product Code'!D:D,""), IF(OR(RIGHT(_xlpm.p,5)="-Door",RIGHT(_xlpm.p,6)="-DOORS"),_xlpm.productType&" - Door",_xlpm.productType) )} -> x | J4: x | K4: 12 | L4: 34.5 | M4: 24 | N4: 1 | O4: 1
A5: F9-B15 | B5: 822 | C5: =B5*0.3 -> 246.6 | D5: =C5*1.13 -> 278.658 | E5: =_xlfn.TEXTAFTER(A5,"-") -> B15 | F5: {=_xlfn.LET( _xlpm.p,E5, _xlpm.code,IFERROR( IF(AND(LEFT(_xlpm.p,2)="DB",ISNUMBER(SEARCH("-2",_xlpm.p))),"DB-2", IF(LEFT(_xlpm.p,3)="OC-","OC", LEFT(_xlpm.p,_xlfn.XMATCH(TRUE,ISNUMBER(--MID(_xlpm.p,_xlfn.SEQUENCE(LEN(_xlpm.p)),1)))-1) ) ), _xlpm.p ), _xlpm.productType,_xlfn.XLOOKUP(_xlpm.code,'Product Code'!A:A,'Product Code'!B:B,""), IF(OR(RIGHT(_xlpm.p,5)="-Door",RIGHT(_xlpm.p,6)="-DOORS"),_xlpm.productType&" - Door",_xlpm.productType) )} -> Base Cabinet | G5: {=_xlfn.LET( _xlpm.p,E5, _xlpm.code,IFERROR( IF(AND(LEFT(_xlpm.p,2)="DB",ISNUMBER(SEARCH("-2",_xlpm.p))),"DB-2", IF(LEFT(_xlpm.p,3)="OC-","OC", LEFT(_xlpm.p,_xlfn.XMATCH(TRUE,ISNUMBER(--MID(_xlpm.p,_xlfn.SEQUENCE(LEN(_xlpm.p)),1)))-1) ) ), _xlpm.p ), _xlpm.base,_xlfn.XLOOKUP(_xlpm.code,'Product Code'!A:A,'Product Code'!C:C,""), IF(RIGHT(_xlpm.p,3)="-PO",_xlpm.base&" - Pull-Out",_xlpm.base) )} -> Standard | H5: Complete Cabinet | I5: {=_xlfn.LET( _xlpm.p,E5, _xlpm.code,IFERROR( IF(AND(LEFT(_xlpm.p,2)="DB",ISNUMBER(SEARCH("-2",_xlpm.p))),"DB-2", IF(LEFT(_xlpm.p,3)="OC-","OC", LEFT(_xlpm.p,_xlfn.XMATCH(TRUE,ISNUMBER(--MID(_xlpm.p,_xlfn.SEQUENCE(LEN(_xlpm.p)),1)))-1) ) ), _xlpm.p ), _xlpm.productType,_xlfn.XLOOKUP(_xlpm.code,'Product Code'!A:A,'Product Code'!D:D,""), IF(OR(RIGHT(_xlpm.p,5)="-Door",RIGHT(_xlpm.p,6)="-DOORS"),_xlpm.productType&" - Door",_xlpm.productType) )} -> x | J5: x | K5: 15 | L5: 34.5 | M5: 24 | N5: 0 | O5: 1
A6: F9-B18 | B6: 883 | C6: =B6*0.3 -> 264.9 | D6: =C6*1.13 -> 299.337 | E6: =_xlfn.TEXTAFTER(A6,"-") -> B18 | F6: {=_xlfn.LET( _xlpm.p,E6, _xlpm.code,IFERROR( IF(AND(LEFT(_xlpm.p,2)="DB",ISNUMBER(SEARCH("-2",_xlpm.p))),"DB-2", IF(LEFT(_xlpm.p,3)="OC-","OC", LEFT(_xlpm.p,_xlfn.XMATCH(TRUE,ISNUMBER(--MID(_xlpm.p,_xlfn.SEQUENCE(LEN(_xlpm.p)),1)))-1) ) ), _xlpm.p ), _xlpm.productType,_xlfn.XLOOKUP(_xlpm.code,'Product Code'!A:A,'Product Code'!B:B,""), IF(OR(RIGHT(_xlpm.p,5)="-Door",RIGHT(_xlpm.p,6)="-DOORS"),_xlpm.productType&" - Door",_xlpm.productType) )} -> Base Cabinet | G6: {=_xlfn.LET( _xlpm.p,E6, _xlpm.code,IFERROR( IF(AND(LEFT(_xlpm.p,2)="DB",ISNUMBER(SEARCH("-2",_xlpm.p))),"DB-2", IF(LEFT(_xlpm.p,3)="OC-","OC", LEFT(_xlpm.p,_xlfn.XMATCH(TRUE,ISNUMBER(--MID(_xlpm.p,_xlfn.SEQUENCE(LEN(_xlpm.p)),1)))-1) ) ), _xlpm.p ), _xlpm.base,_xlfn.XLOOKUP(_xlpm.code,'Product Code'!A:A,'Product Code'!C:C,""), IF(RIGHT(_xlpm.p,3)="-PO",_xlpm.base&" - Pull-Out",_xlpm.base) )} -> Standard | H6: Complete Cabinet | I6: {=_xlfn.LET( _xlpm.p,E6, _xlpm.code,IFERROR( IF(AND(LEFT(_xlpm.p,2)="DB",ISNUMBER(SEARCH("-2",_xlpm.p))),"DB-2", IF(LEFT(_xlpm.p,3)="OC-","OC", LEFT(_xlpm.p,_xlfn.XMATCH(TRUE,ISNUMBER(--MID(_xlpm.p,_xlfn.SEQUENCE(LEN(_xlpm.p)),1)))-1) ) ), _xlpm.p ), _xlpm.productType,_xlfn.XLOOKUP(_xlpm.code,'Product Code'!A:A,'Product Code'!D:D,""), IF(OR(RIGHT(_xlpm.p,5)="-Door",RIGHT(_xlpm.p,6)="-DOORS"),_xlpm.productType&" - Door",_xlpm.productType) )} -> x | J6: x | K6: 18 | L6: 34.5 | M6: 24 | N6: 1 | O6: 1
A7: F9-B18-PO | B7: 1060 | C7: =B7*0.3 -> 318 | D7: =C7*1.13 -> 359.34 | E7: =_xlfn.TEXTAFTER(A7,"-") -> B18-PO | F7: {=_xlfn.LET( _xlpm.p,E7, _xlpm.code,IFERROR( IF(AND(LEFT(_xlpm.p,2)="DB",ISNUMBER(SEARCH("-2",_xlpm.p))),"DB-2", IF(LEFT(_xlpm.p,3)="OC-","OC", LEFT(_xlpm.p,_xlfn.XMATCH(TRUE,ISNUMBER(--MID(_xlpm.p,_xlfn.SEQUENCE(LEN(_xlpm.p)),1)))-1) ) ), _xlpm.p ), _xlpm.productType,_xlfn.XLOOKUP(_xlpm.code,'Product Code'!A:A,'Product Code'!B:B,""), IF(OR(RIGHT(_xlpm.p,5)="-Door",RIGHT(_xlpm.p,6)="-DOORS"),_xlpm.productType&" - Door",_xlpm.productType) )} -> Base Cabinet | G7: {=_xlfn.LET( _xlpm.p,E7, _xlpm.code,IFERROR( IF(AND(LEFT(_xlpm.p,2)="DB",ISNUMBER(SEARCH("-2",_xlpm.p))),"DB-2", IF(LEFT(_xlpm.p,3)="OC-","OC", LEFT(_xlpm.p,_xlfn.XMATCH(TRUE,ISNUMBER(--MID(_xlpm.p,_xlfn.SEQUENCE(LEN(_xlpm.p)),1)))-1) ) ), _xlpm.p ), _xlpm.base,_xlfn.XLOOKUP(_xlpm.code,'Product Code'!A:A,'Product Code'!C:C,""), IF(RIGHT(_xlpm.p,3)="-PO",_xlpm.base&" - Pull-Out",_xlpm.base) )} -> Standard - Pull-Out | H7: Complete Cabinet, for garbage bin | I7: {=_xlfn.LET( _xlpm.p,E7, _xlpm.code,IFERROR( IF(AND(LEFT(_xlpm.p,2)="DB",ISNUMBER(SEARCH("-2",_xlpm.p))),"DB-2", IF(LEFT(_xlpm.p,3)="OC-","OC", LEFT(_xlpm.p,_xlfn.XMATCH(TRUE,ISNUMBER(--MID(_xlpm.p,_xlfn.SEQUENCE(LEN(_xlpm.p)),1)))-1) ) ), _xlpm.p ), _xlpm.productType,_xlfn.XLOOKUP(_xlpm.code,'Product Code'!A:A,'Product Code'!D:D,""), IF(OR(RIGHT(_xlpm.p,5)="-Door",RIGHT(_xlpm.p,6)="-DOORS"),_xlpm.productType&" - Door",_xlpm.productType) )} -> x | J7: x | K7: 18 | L7: 34.5 | M7: 24 | N7: 1 | O7: 1
A8: F9-B21 | B8: 925 | C8: =B8*0.3 -> 277.5 | D8: =C8*1.13 -> 313.575 | E8: =_xlfn.TEXTAFTER(A8,"-") -> B21 | F8: {=_xlfn.LET( _xlpm.p,E8, _xlpm.code,IFERROR( IF(AND(LEFT(_xlpm.p,2)="DB",ISNUMBER(SEARCH("-2",_xlpm.p))),"DB-2", IF(LEFT(_xlpm.p,3)="OC-","OC", LEFT(_xlpm.p,_xlfn.XMATCH(TRUE,ISNUMBER(--MID(_xlpm.p,_xlfn.SEQUENCE(LEN(_xlpm.p)),1)))-1) ) ), _xlpm.p ), _xlpm.productType,_xlfn.XLOOKUP(_xlpm.code,'Product Code'!A:A,'Product Code'!B:B,""), IF(OR(RIGHT(_xlpm.p,5)="-Door",RIGHT(_xlpm.p,6)="-DOORS"),_xlpm.productType&" - Door",_xlpm.productType) )} -> Base Cabinet | G8: {=_xlfn.LET( _xlpm.p,E8, _xlpm.code,IFERROR( IF(AND(LEFT(_xlpm.p,2)="DB",ISNUMBER(SEARCH("-2",_xlpm.p))),"DB-2", IF(LEFT(_xlpm.p,3)="OC-","OC", LEFT(_xlpm.p,_xlfn.XMATCH(TRUE,ISNUMBER(--MID(_xlpm.p,_xlfn.SEQUENCE(LEN(_xlpm.p)),1)))-1) ) ), _xlpm.p ), _xlpm.base,_xlfn.XLOOKUP(_xlpm.code,'Product Code'!A:A,'Product Code'!C:C,""), IF(RIGHT(_xlpm.p,3)="-PO",_xlpm.base&" - Pull-Out",_xlpm.base) )} -> Standard | H8: Complete Cabinet | I8: {=_xlfn.LET( _xlpm.p,E8, _xlpm.code,IFERROR( IF(AND(LEFT(_xlpm.p,2)="DB",ISNUMBER(SEARCH("-2",_xlpm.p))),"DB-2", IF(LEFT(_xlpm.p,3)="OC-","OC", LEFT(_xlpm.p,_xlfn.XMATCH(TRUE,ISNUMBER(--MID(_xlpm.p,_xlfn.SEQUENCE(LEN(_xlpm.p)),1)))-1) ) ), _xlpm.p ), _xlpm.productType,_xlfn.XLOOKUP(_xlpm.code,'Product Code'!A:A,'Product Code'!D:D,""), IF(OR(RIGHT(_xlpm.p,5)="-Door",RIGHT(_xlpm.p,6)="-DOORS"),_xlpm.productType&" - Door",_xlpm.productType) )} -> x | J8: x | K8: 21 | L8: 34.5 | M8: 24 | N8: 1 | O8: 1
A9: F9-BBC42 | B9: 1203 | C9: =B9*0.3 -> 360.9 | D9: =C9*1.13 -> 407.817 | E9: =_xlfn.TEXTAFTER(A9,"-") -> BBC42 | F9: {=_xlfn.LET( _xlpm.p,E9, _xlpm.code,IFERROR( IF(AND(LEFT(_xlpm.p,2)="DB",ISNUMBER(SEARCH("-2",_xlpm.p))),"DB-2", IF(LEFT(_xlpm.p,3)="OC-","OC", LEFT(_xlpm.p,_xlfn.XMATCH(TRUE,ISNUMBER(--MID(_xlpm.p,_xlfn.SEQUENCE(LEN(_xlpm.p)),1)))-1) ) ), _xlpm.p ), _xlpm.productType,_xlfn.XLOOKUP(_xlpm.code,'Product Code'!A:A,'Product Code'!B:B,""), IF(OR(RIGHT(_xlpm.p,5)="-Door",RIGHT(_xlpm.p,6)="-DOORS"),_xlpm.productType&" - Door",_xlpm.productType) )} -> Base Cabinet | G9: {=_xlfn.LET( _xlpm.p,E9, _xlpm.code,IFERROR( IF(AND(LEFT(_xlpm.p,2)="DB",ISNUMBER(SEARCH("-2",_xlpm.p))),"DB-2", IF(LEFT(_xlpm.p,3)="OC-","OC", LEFT(_xlpm.p,_xlfn.XMATCH(TRUE,ISNUMBER(--MID(_xlpm.p,_xlfn.SEQUENCE(LEN(_xlpm.p)),1)))-1) ) ), _xlpm.p ), _xlpm.base,_xlfn.XLOOKUP(_xlpm.code,'Product Code'!A:A,'Product Code'!C:C,""), IF(RIGHT(_xlpm.p,3)="-PO",_xlpm.base&" - Pull-Out",_xlpm.base) )} -> Blind Corner | H9: Complete Cabinet | I9: {=_xlfn.LET( _xlpm.p,E9, _xlpm.code,IFERROR( IF(AND(LEFT(_xlpm.p,2)="DB",ISNUMBER(SEARCH("-2",_xlpm.p))),"DB-2", IF(LEFT(_xlpm.p,3)="OC-","OC", LEFT(_xlpm.p,_xlfn.XMATCH(TRUE,ISNUMBER(--MID(_xlpm.p,_xlfn.SEQUENCE(LEN(_xlpm.p)),1)))-1) ) ), _xlpm.p ), _xlpm.productType,_xlfn.XLOOKUP(_xlpm.code,'Product Code'!A:A,'Product Code'!D:D,""), IF(OR(RIGHT(_xlpm.p,5)="-Door",RIGHT(_xlpm.p,6)="-DOORS"),_xlpm.productType&" - Door",_xlpm.productType) )} -> x | J9: x | K9: 42 | L9: 34.5 | M9: 24 | N9: 1 | O9: 1
A10: F9-BBC45 | B10: 1303 | C10: =B10*0.3 -> 390.9 | D10: =C10*1.13 -> 441.717 | E10: =_xlfn.TEXTAFTER(A10,"-") -> BBC45 | F10: {=_xlfn.LET( _xlpm.p,E10, _xlpm.code,IFERROR( IF(AND(LEFT(_xlpm.p,2)="DB",ISNUMBER(SEARCH("-2",_xlpm.p))),"DB-2", IF(LEFT(_xlpm.p,3)="OC-","OC", LEFT(_xlpm.p,_xlfn.XMATCH(TRUE,ISNUMBER(--MID(_xlpm.p,_xlfn.SEQUENCE(LEN(_xlpm.p)),1)))-1) ) ), _xlpm.p ), _xlpm.productType,_xlfn.XLOOKUP(_xlpm.code,'Product Code'!A:A,'Product Code'!B:B,""), IF(OR(RIGHT(_xlpm.p,5)="-Door",RIGHT(_xlpm.p,6)="-DOORS"),_xlpm.productType&" - Door",_xlpm.productType) )} -> Base Cabinet | G10: {=_xlfn.LET( _xlpm.p,E10, _xlpm.code,IFERROR( IF(AND(LEFT(_xlpm.p,2)="DB",ISNUMBER(SEARCH("-2",_xlpm.p))),"DB-2", IF(LEFT(_xlpm.p,3)="OC-","OC", LEFT(_xlpm.p,_xlfn.XMATCH(TRUE,ISNUMBER(--MID(_xlpm.p,_xlfn.SEQUENCE(LEN(_xlpm.p)),1)))-1) ) ), _xlpm.p ), _xlpm.base,_xlfn.XLOOKUP(_xlpm.code,'Product Code'!A:A,'Product Code'!C:C,""), IF(RIGHT(_xlpm.p,3)="-PO",_xlpm.base&" - Pull-Out",_xlpm.base) )} -> Blind Corner | H10: Complete Cabinet | I10: {=_xlfn.LET( _xlpm.p,E10, _xlpm.code,IFERROR( IF(AND(LEFT(_xlpm.p,2)="DB",ISNUMBER(SEARCH("-2",_xlpm.p))),"DB-2", IF(LEFT(_xlpm.p,3)="OC-","OC", LEFT(_xlpm.p,_xlfn.XMATCH(TRUE,ISNUMBER(--MID(_xlpm.p,_xlfn.SEQUENCE(LEN(_xlpm.p)),1)))-1) ) ), _xlpm.p ), _xlpm.productType,_xlfn.XLOOKUP(_xlpm.code,'Product Code'!A:A,'Product Code'!D:D,""), IF(OR(RIGHT(_xlpm.p,5)="-Door",RIGHT(_xlpm.p,6)="-DOORS"),_xlpm.productType&" - Door",_xlpm.productType) )} -> x | J10: x | K10: 45 | L10: 34.5 | M10: 24 | N10: =IF(ISNUMBER(SEARCH("Cabinet",F10))=FALSE,"N/A",IF(K10>=24,2,1)) -> 2 | O10: =IF(ISNUMBER(SEARCH("Cabinet",F10))=FALSE,"N/A", IF(ISNUMBER(SEARCH("DB",E10)), IF(ISNUMBER(SEARCH("-2",E10)),2,3), IF(ISNUMBER(SEARCH("-PO",E10)),1, IF(LEFT(E10,1)="B",1,0) ) ) ) -> 1
A11: F9-BBC48 | B11: 1404 | C11: =B11*0.3 -> 421.2 | D11: =C11*1.13 -> 475.956 | E11: =_xlfn.TEXTAFTER(A11,"-") -> BBC48 | F11: {=_xlfn.LET( _xlpm.p,E11, _xlpm.code,IFERROR( IF(AND(LEFT(_xlpm.p,2)="DB",ISNUMBER(SEARCH("-2",_xlpm.p))),"DB-2", IF(LEFT(_xlpm.p,3)="OC-","OC", LEFT(_xlpm.p,_xlfn.XMATCH(TRUE,ISNUMBER(--MID(_xlpm.p,_xlfn.SEQUENCE(LEN(_xlpm.p)),1)))-1) ) ), _xlpm.p ), _xlpm.productType,_xlfn.XLOOKUP(_xlpm.code,'Product Code'!A:A,'Product Code'!B:B,""), IF(OR(RIGHT(_xlpm.p,5)="-Door",RIGHT(_xlpm.p,6)="-DOORS"),_xlpm.productType&" - Door",_xlpm.productType) )} -> Base Cabinet | G11: {=_xlfn.LET( _xlpm.p,E11, _xlpm.code,IFERROR( IF(AND(LEFT(_xlpm.p,2)="DB",ISNUMBER(SEARCH("-2",_xlpm.p))),"DB-2", IF(LEFT(_xlpm.p,3)="OC-","OC", LEFT(_xlpm.p,_xlfn.XMATCH(TRUE,ISNUMBER(--MID(_xlpm.p,_xlfn.SEQUENCE(LEN(_xlpm.p)),1)))-1) ) ), _xlpm.p ), _xlpm.base,_xlfn.XLOOKUP(_xlpm.code,'Product Code'!A:A,'Product Code'!C:C,""), IF(RIGHT(_xlpm.p,3)="-PO",_xlpm.base&" - Pull-Out",_xlpm.base) )} -> Blind Corner | H11: Complete Cabinet | I11: {=_xlfn.LET( _xlpm.p,E11, _xlpm.code,IFERROR( IF(AND(LEFT(_xlpm.p,2)="DB",ISNUMBER(SEARCH("-2",_xlpm.p))),"DB-2", IF(LEFT(_xlpm.p,3)="OC-","OC", LEFT(_xlpm.p,_xlfn.XMATCH(TRUE,ISNUMBER(--MID(_xlpm.p,_xlfn.SEQUENCE(LEN(_xlpm.p)),1)))-1) ) ), _xlpm.p ), _xlpm.productType,_xlfn.XLOOKUP(_xlpm.code,'Product Code'!A:A,'Product Code'!D:D,""), IF(OR(RIGHT(_xlpm.p,5)="-Door",RIGHT(_xlpm.p,6)="-DOORS"),_xlpm.productType&" - Door",_xlpm.productType) )} -> x | J11: x | K11: 48 | L11: 34.5 | M11: 24 | N11: =IF(ISNUMBER(SEARCH("Cabinet",F11))=FALSE,"N/A",IF(K11>=24,2,1)) -> 2 | O11: =IF(ISNUMBER(SEARCH("Cabinet",F11))=FALSE,"N/A", IF(ISNUMBER(SEARCH("DB",E11)), IF(ISNUMBER(SEARCH("-2",E11)),2,3), IF(ISNUMBER(SEARCH("-PO",E11)),1, IF(LEFT(E11,1)="B",1,0) ) ) ) -> 1
A12: F9-DB12 | B12: 1059 | C12: =B12*0.3 -> 317.7 | D12: =C12*1.13 -> 359.001 | E12: =_xlfn.TEXTAFTER(A12,"-") -> DB12 | F12: {=_xlfn.LET( _xlpm.p,E12, _xlpm.code,IFERROR( IF(AND(LEFT(_xlpm.p,2)="DB",ISNUMBER(SEARCH("-2",_xlpm.p))),"DB-2", IF(LEFT(_xlpm.p,3)="OC-","OC", LEFT(_xlpm.p,_xlfn.XMATCH(TRUE,ISNUMBER(--MID(_xlpm.p,_xlfn.SEQUENCE(LEN(_xlpm.p)),1)))-1) ) ), _xlpm.p ), _xlfn.XLOOKUP(_xlpm.code,'Product Code'!A:A,'Product Code'!B:B,"") )} -> Base Cabinet | G12: Drawer | H12: Complete Cabinet | I12: {=_xlfn.LET( _xlpm.p,E12, _xlpm.code,IFERROR( IF(AND(LEFT(_xlpm.p,2)="DB",ISNUMBER(SEARCH("-2",_xlpm.p))),"DB-2", IF(LEFT(_xlpm.p,3)="OC-","OC", LEFT(_xlpm.p,_xlfn.XMATCH(TRUE,ISNUMBER(--MID(_xlpm.p,_xlfn.SEQUENCE(LEN(_xlpm.p)),1)))-1) ) ), _xlpm.p ), _xlpm.productType,_xlfn.XLOOKUP(_xlpm.code,'Product Code'!A:A,'Product Code'!D:D,""), IF(OR(RIGHT(_xlpm.p,5)="-Door",RIGHT(_xlpm.p,6)="-DOORS"),_xlpm.productType&" - Door",_xlpm.productType) )} -> x | J12: x | K12: 12 | L12: 34.5 | M12: 24 | N12: =IF(ISNUMBER(SEARCH("Cabinet",F12))=FALSE,"N/A",IF(K12>=24,2,1)) -> 1 | O12: =IF(ISNUMBER(SEARCH("Cabinet",F12))=FALSE,"N/A", IF(ISNUMBER(SEARCH("DB",E12)), IF(ISNUMBER(SEARCH("-2",E12)),2,3), IF(ISNUMBER(SEARCH("-PO",E12)),1, IF(LEFT(E12,1)="B",1,0) ) ) ) -> 3
A13: F9-DB15 | B13: 1157 | C13: =B13*0.3 -> 347.1 | D13: =C13*1.13 -> 392.223 | E13: =_xlfn.TEXTAFTER(A13,"-") -> DB15 | F13: {=_xlfn.LET( _xlpm.p,E13, _xlpm.code,IFERROR( IF(AND(LEFT(_xlpm.p,2)="DB",ISNUMBER(SEARCH("-2",_xlpm.p))),"DB-2", IF(LEFT(_xlpm.p,3)="OC-","OC", LEFT(_xlpm.p,_xlfn.XMATCH(TRUE,ISNUMBER(--MID(_xlpm.p,_xlfn.SEQUENCE(LEN(_xlpm.p)),1)))-1) ) ), _xlpm.p ), _xlfn.XLOOKUP(_xlpm.code,'Product Code'!A:A,'Product Code'!B:B,"") )} -> Base Cabinet | G13: Drawer | H13: Complete Cabinet | I13: {=_xlfn.LET( _xlpm.p,E13, _xlpm.code,IFERROR( IF(AND(LEFT(_xlpm.p,2)="DB",ISNUMBER(SEARCH("-2",_xlpm.p))),"DB-2", IF(LEFT(_xlpm.p,3)="OC-","OC", LEFT(_xlpm.p,_xlfn.XMATCH(TRUE,ISNUMBER(--MID(_xlpm.p,_xlfn.SEQUENCE(LEN(_xlpm.p)),1)))-1) ) ), _xlpm.p ), _xlpm.productType,_xlfn.XLOOKUP(_xlpm.code,'Product Code'!A:A,'Product Code'!D:D,""), IF(OR(RIGHT(_xlpm.p,5)="-Door",RIGHT(_xlpm.p,6)="-DOORS"),_xlpm.productType&" - Door",_xlpm.productType) )} -> x | J13: x | K13: 15 | L13: 34.5 | M13: 24 | N13: =IF(ISNUMBER(SEARCH("Cabinet",F13))=FALSE,"N/A",IF(K13>=24,2,1)) -> 1 | O13: =IF(ISNUMBER(SEARCH("Cabinet",F13))=FALSE,"N/A", IF(ISNUMBER(SEARCH("DB",E13)), IF(ISNUMBER(SEARCH("-2",E13)),2,3), IF(ISNUMBER(SEARCH("-PO",E13)),1, IF(LEFT(E13,1)="B",1,0) ) ) ) -> 3
A14: F9-DB18 | B14: 1202 | C14: =B14*0.3 -> 360.6 | D14: =C14*1.13 -> 407.478 | E14: =_xlfn.TEXTAFTER(A14,"-") -> DB18 | F14: {=_xlfn.LET( _xlpm.p,E14, _xlpm.code,IFERROR( IF(AND(LEFT(_xlpm.p,2)="DB",ISNUMBER(SEARCH("-2",_xlpm.p))),"DB-2", IF(LEFT(_xlpm.p,3)="OC-","OC", LEFT(_xlpm.p,_xlfn.XMATCH(TRUE,ISNUMBER(--MID(_xlpm.p,_xlfn.SEQUENCE(LEN(_xlpm.p)),1)))-1) ) ), _xlpm.p ), _xlfn.XLOOKUP(_xlpm.code,'Product Code'!A:A,'Product Code'!B:B,"") )} -> Base Cabinet | G14: Drawer | H14: Complete Cabinet | I14: {=_xlfn.LET( _xlpm.p,E14, _xlpm.code,IFERROR( IF(AND(LEFT(_xlpm.p,2)="DB",ISNUMBER(SEARCH("-2",_xlpm.p))),"DB-2", IF(LEFT(_xlpm.p,3)="OC-","OC", LEFT(_xlpm.p,_xlfn.XMATCH(TRUE,ISNUMBER(--MID(_xlpm.p,_xlfn.SEQUENCE(LEN(_xlpm.p)),1)))-1) ) ), _xlpm.p ), _xlpm.productType,_xlfn.XLOOKUP(_xlpm.code,'Product Code'!A:A,'Product Code'!D:D,""), IF(OR(RIGHT(_xlpm.p,5)="-Door",RIGHT(_xlpm.p,6)="-DOORS"),_xlpm.productType&" - Door",_xlpm.productType) )} -> x | J14: x | K14: 18 | L14: 34.5 | M14: 24 | N14: =IF(ISNUMBER(SEARCH("Cabinet",F14))=FALSE,"N/A",IF(K14>=24,2,1)) -> 1 | O14: =IF(ISNUMBER(SEARCH("Cabinet",F14))=FALSE,"N/A", IF(ISNUMBER(SEARCH("DB",E14)), IF(ISNUMBER(SEARCH("-2",E14)),2,3), IF(ISNUMBER(SEARCH("-PO",E14)),1, IF(LEFT(E14,1)="B",1,0) ) ) ) -> 3
A15: F9-DB21 | B15: 1306 | C15: =B15*0.3 -> 391.8 | D15: =C15*1.13 -> 442.734 | E15: =_xlfn.TEXTAFTER(A15,"-") -> DB21 | F15: {=_xlfn.LET( _xlpm.p,E15, _xlpm.code,IFERROR( IF(AND(LEFT(_xlpm.p,2)="DB",ISNUMBER(SEARCH("-2",_xlpm.p))),"DB-2", IF(LEFT(_xlpm.p,3)="OC-","OC", LEFT(_xlpm.p,_xlfn.XMATCH(TRUE,ISNUMBER(--MID(_xlpm.p,_xlfn.SEQUENCE(LEN(_xlpm.p)),1)))-1) ) ), _xlpm.p ), _xlfn.XLOOKUP(_xlpm.code,'Product Code'!A:A,'Product Code'!B:B,"") )} -> Base Cabinet | G15: Drawer | H15: Complete Cabinet | I15: {=_xlfn.LET( _xlpm.p,E15, _xlpm.code,IFERROR( IF(AND(LEFT(_xlpm.p,2)="DB",ISNUMBER(SEARCH("-2",_xlpm.p))),"DB-2", IF(LEFT(_xlpm.p,3)="OC-","OC", LEFT(_xlpm.p,_xlfn.XMATCH(TRUE,ISNUMBER(--MID(_xlpm.p,_xlfn.SEQUENCE(LEN(_xlpm.p)),1)))-1) ) ), _xlpm.p ), _xlpm.productType,_xlfn.XLOOKUP(_xlpm.code,'Product Code'!A:A,'Product Code'!D:D,""), IF(OR(RIGHT(_xlpm.p,5)="-Door",RIGHT(_xlpm.p,6)="-DOORS"),_xlpm.productType&" - Door",_xlpm.productType) )} -> x | J15: x | K15: 21 | L15: 34.5 | M15: 24 | N15: =IF(ISNUMBER(SEARCH("Cabinet",F15))=FALSE,"N/A",IF(K15>=24,2,1)) -> 1 | O15: =IF(ISNUMBER(SEARCH("Cabinet",F15))=FALSE,"N/A", IF(ISNUMBER(SEARCH("DB",E15)), IF(ISNUMBER(SEARCH("-2",E15)),2,3), IF(ISNUMBER(SEARCH("-PO",E15)),1, IF(LEFT(E15,1)="B",1,0) ) ) ) -> 3
A16: F9-DB24 | B16: 1346 | C16: =B16*0.3 -> 403.8 | D16: =C16*1.13 -> 456.294 | E16: =_xlfn.TEXTAFTER(A16,"-") -> DB24 | F16: {=_xlfn.LET( _xlpm.p,E16, _xlpm.code,IFERROR( IF(AND(LEFT(_xlpm.p,2)="DB",ISNUMBER(SEARCH("-2",_xlpm.p))),"DB-2", IF(LEFT(_xlpm.p,3)="OC-","OC", LEFT(_xlpm.p,_xlfn.XMATCH(TRUE,ISNUMBER(--MID(_xlpm.p,_xlfn.SEQUENCE(LEN(_xlpm.p)),1)))-1) ) ), _xlpm.p ), _xlfn.XLOOKUP(_xlpm.code,'Product Code'!A:A,'Product Code'!B:B,"") )} -> Base Cabinet | G16: Drawer | H16: Complete Cabinet | I16: {=_xlfn.LET( _xlpm.p,E16, _xlpm.code,IFERROR( IF(AND(LEFT(_xlpm.p,2)="DB",ISNUMBER(SEARCH("-2",_xlpm.p))),"DB-2", IF(LEFT(_xlpm.p,3)="OC-","OC", LEFT(_xlpm.p,_xlfn.XMATCH(TRUE,ISNUMBER(--MID(_xlpm.p,_xlfn.SEQUENCE(LEN(_xlpm.p)),1)))-1) ) ), _xlpm.p ), _xlpm.productType,_xlfn.XLOOKUP(_xlpm.code,'Product Code'!A:A,'Product Code'!D:D,""), IF(OR(RIGHT(_xlpm.p,5)="-Door",RIGHT(_xlpm.p,6)="-DOORS"),_xlpm.productType&" - Door",_xlpm.productType) )} -> x | J16: x | K16: 24 | L16: 34.5 | M16: 24 | N16: =IF(ISNUMBER(SEARCH("Cabinet",F16))=FALSE,"N/A",IF(K16>=24,2,1)) -> 2 | O16: =IF(ISNUMBER(SEARCH("Cabinet",F16))=FALSE,"N/A", IF(ISNUMBER(SEARCH("DB",E16)), IF(ISNUMBER(SEARCH("-2",E16)),2,3), IF(ISNUMBER(SEARCH("-PO",E16)),1, IF(LEFT(E16,1)="B",1,0) ) ) ) -> 3
A17: F9-DB27 | B17: 1419 | C17: =B17*0.3 -> 425.7 | D17: =C17*1.13 -> 481.041 | E17: =_xlfn.TEXTAFTER(A17,"-") -> DB27 | F17: {=_xlfn.LET( _xlpm.p,E17, _xlpm.code,IFERROR( IF(AND(LEFT(_xlpm.p,2)="DB",ISNUMBER(SEARCH("-2",_xlpm.p))),"DB-2", IF(LEFT(_xlpm.p,3)="OC-","OC", LEFT(_xlpm.p,_xlfn.XMATCH(TRUE,ISNUMBER(--MID(_xlpm.p,_xlfn.SEQUENCE(LEN(_xlpm.p)),1)))-1) ) ), _xlpm.p ), _xlfn.XLOOKUP(_xlpm.code,'Product Code'!A:A,'Product Code'!B:B,"") )} -> Base Cabinet | G17: Drawer | H17: Complete Cabinet | I17: {=_xlfn.LET( _xlpm.p,E17, _xlpm.code,IFERROR( IF(AND(LEFT(_xlpm.p,2)="DB",ISNUMBER(SEARCH("-2",_xlpm.p))),"DB-2", IF(LEFT(_xlpm.p,3)="OC-","OC", LEFT(_xlpm.p,_xlfn.XMATCH(TRUE,ISNUMBER(--MID(_xlpm.p,_xlfn.SEQUENCE(LEN(_xlpm.p)),1)))-1) ) ), _xlpm.p ), _xlpm.productType,_xlfn.XLOOKUP(_xlpm.code,'Product Code'!A:A,'Product Code'!D:D,""), IF(OR(RIGHT(_xlpm.p,5)="-Door",RIGHT(_xlpm.p,6)="-DOORS"),_xlpm.productType&" - Door",_xlpm.productType) )} -> x | J17: x | K17: 27 | L17: 34.5 | M17: 24 | N17: =IF(ISNUMBER(SEARCH("Cabinet",F17))=FALSE,"N/A",IF(K17>=24,2,1)) -> 2 | O17: =IF(ISNUMBER(SEARCH("Cabinet",F17))=FALSE,"N/A", IF(ISNUMBER(SEARCH("DB",E17)), IF(ISNUMBER(SEARCH("-2",E17)),2,3), IF(ISNUMBER(SEARCH("-PO",E17)),1, IF(LEFT(E17,1)="B",1,0) ) ) ) -> 3
A18: F9-DB27-2 | B18: 1122 | C18: =B18*0.3 -> 336.6 | D18: =C18*1.13 -> 380.358 | E18: =_xlfn.TEXTAFTER(A18,"-") -> DB27-2 | F18: {=_xlfn.LET( _xlpm.p,E18, _xlpm.code,IFERROR( IF(AND(LEFT(_xlpm.p,2)="DB",ISNUMBER(SEARCH("-2",_xlpm.p))),"DB-2", IF(LEFT(_xlpm.p,3)="OC-","OC", LEFT(_xlpm.p,_xlfn.XMATCH(TRUE,ISNUMBER(--MID(_xlpm.p,_xlfn.SEQUENCE(LEN(_xlpm.p)),1)))-1) ) ), _xlpm.p ), _xlfn.XLOOKUP(_xlpm.code,'Product Code'!A:A,'Product Code'!B:B,"") )} -> Base Cabinet | G18: Drawer | H18: Complete Cabinet | I18: {=_xlfn.LET( _xlpm.p,E18, _xlpm.code,IFERROR( IF(AND(LEFT(_xlpm.p,2)="DB",ISNUMBER(SEARCH("-2",_xlpm.p))),"DB-2", IF(LEFT(_xlpm.p,3)="OC-","OC", LEFT(_xlpm.p,_xlfn.XMATCH(TRUE,ISNUMBER(--MID(_xlpm.p,_xlfn.SEQUENCE(LEN(_xlpm.p)),1)))-1) ) ), _xlpm.p ), _xlpm.productType,_xlfn.XLOOKUP(_xlpm.code,'Product Code'!A:A,'Product Code'!D:D,""), IF(OR(RIGHT(_xlpm.p,5)="-Door",RIGHT(_xlpm.p,6)="-DOORS"),_xlpm.productType&" - Door",_xlpm.productType) )} -> x | J18: x | K18: 27 | L18: 34.5 | M18: 24 | N18: =IF(ISNUMBER(SEARCH("Cabinet",F18))=FALSE,"N/A",IF(K18>=24,2,1)) -> 2 | O18: =IF(ISNUMBER(SEARCH("Cabinet",F18))=FALSE,"N/A", IF(ISNUMBER(SEARCH("DB",E18)), IF(ISNUMBER(SEARCH("-2",E18)),2,3), IF(ISNUMBER(SEARCH("-PO",E18)),1, IF(LEFT(E18,1)="B",1,0) ) ) ) -> 2
A19: F9-DB30 | B19: 1490 | C19: =B19*0.3 -> 447 | D19: =C19*1.13 -> 505.11 | E19: =_xlfn.TEXTAFTER(A19,"-") -> DB30 | F19: {=_xlfn.LET( _xlpm.p,E19, _xlpm.code,IFERROR( IF(AND(LEFT(_xlpm.p,2)="DB",ISNUMBER(SEARCH("-2",_xlpm.p))),"DB-2", IF(LEFT(_xlpm.p,3)="OC-","OC", LEFT(_xlpm.p,_xlfn.XMATCH(TRUE,ISNUMBER(--MID(_xlpm.p,_xlfn.SEQUENCE(LEN(_xlpm.p)),1)))-1) ) ), _xlpm.p ), _xlfn.XLOOKUP(_xlpm.code,'Product Code'!A:A,'Product Code'!B:B,"") )} -> Base Cabinet | G19: Drawer | H19: Complete Cabinet | I19: {=_xlfn.LET( _xlpm.p,E19, _xlpm.code,IFERROR( IF(AND(LEFT(_xlpm.p,2)="DB",ISNUMBER(SEARCH("-2",_xlpm.p))),"DB-2", IF(LEFT(_xlpm.p,3)="OC-","OC", LEFT(_xlpm.p,_xlfn.XMATCH(TRUE,ISNUMBER(--MID(_xlpm.p,_xlfn.SEQUENCE(LEN(_xlpm.p)),1)))-1) ) ), _xlpm.p ), _xlpm.productType,_xlfn.XLOOKUP(_xlpm.code,'Product Code'!A:A,'Product Code'!D:D,""), IF(OR(RIGHT(_xlpm.p,5)="-Door",RIGHT(_xlpm.p,6)="-DOORS"),_xlpm.productType&" - Door",_xlpm.productType) )} -> x | J19: x | K19: 30 | L19: 34.5 | M19: 24 | N19: =IF(ISNUMBER(SEARCH("Cabinet",F19))=FALSE,"N/A",IF(K19>=24,2,1)) -> 2 | O19: =IF(ISNUMBER(SEARCH("Cabinet",F19))=FALSE,"N/A", IF(ISNUMBER(SEARCH("DB",E19)), IF(ISNUMBER(SEARCH("-2",E19)),2,3), IF(ISNUMBER(SEARCH("-PO",E19)),1, IF(LEFT(E19,1)="B",1,0) ) ) ) -> 3
A20: F9-DB30-2 | B20: 1211 | C20: =B20*0.3 -> 363.3 | D20: =C20*1.13 -> 410.529 | E20: =_xlfn.TEXTAFTER(A20,"-") -> DB30-2 | F20: {=_xlfn.LET( _xlpm.p,E20, _xlpm.code,IFERROR( IF(AND(LEFT(_xlpm.p,2)="DB",ISNUMBER(SEARCH("-2",_xlpm.p))),"DB-2", IF(LEFT(_xlpm.p,3)="OC-","OC", LEFT(_xlpm.p,_xlfn.XMATCH(TRUE,ISNUMBER(--MID(_xlpm.p,_xlfn.SEQUENCE(LEN(_xlpm.p)),1)))-1) ) ), _xlpm.p ), _xlfn.XLOOKUP(_xlpm.code,'Product Code'!A:A,'Product Code'!B:B,"") )} -> Base Cabinet | G20: Drawer | H20: Complete Cabinet | I20: {=_xlfn.LET( _xlpm.p,E20, _xlpm.code,IFERROR( IF(AND(LEFT(_xlpm.p,2)="DB",ISNUMBER(SEARCH("-2",_xlpm.p))),"DB-2", IF(LEFT(_xlpm.p,3)="OC-","OC", LEFT(_xlpm.p,_xlfn.XMATCH(TRUE,ISNUMBER(--MID(_xlpm.p,_xlfn.SEQUENCE(LEN(_xlpm.p)),1)))-1) ) ), _xlpm.p ), _xlpm.productType,_xlfn.XLOOKUP(_xlpm.code,'Product Code'!A:A,'Product Code'!D:D,""), IF(OR(RIGHT(_xlpm.p,5)="-Door",RIGHT(_xlpm.p,6)="-DOORS"),_xlpm.productType&" - Door",_xlpm.productType) )} -> x | J20: x | K20: 30 | L20: 34.5 | M20: 24 | N20: =IF(ISNUMBER(SEARCH("Cabinet",F20))=FALSE,"N/A",IF(K20>=24,2,1)) -> 2 | O20: =IF(ISNUMBER(SEARCH("Cabinet",F20))=FALSE,"N/A", IF(ISNUMBER(SEARCH("DB",E20)), IF(ISNUMBER(SEARCH("-2",E20)),2,3), IF(ISNUMBER(SEARCH("-PO",E20)),1, IF(LEFT(E20,1)="B",1,0) ) ) ) -> 2
A21: F9-DB33 | B21: 1552 | C21: =B21*0.3 -> 465.6 | D21: =C21*1.13 -> 526.128 | E21: =_xlfn.TEXTAFTER(A21,"-") -> DB33 | F21: {=_xlfn.LET( _xlpm.p,E21, _xlpm.code,IFERROR( IF(AND(LEFT(_xlpm.p,2)="DB",ISNUMBER(SEARCH("-2",_xlpm.p))),"DB-2", IF(LEFT(_xlpm.p,3)="OC-","OC", LEFT(_xlpm.p,_xlfn.XMATCH(TRUE,ISNUMBER(--MID(_xlpm.p,_xlfn.SEQUENCE(LEN(_xlpm.p)),1)))-1) ) ), _xlpm.p ), _xlfn.XLOOKUP(_xlpm.code,'Product Code'!A:A,'Product Code'!B:B,"") )} -> Base Cabinet | G21: Drawer | H21: Complete Cabinet | I21: {=_xlfn.LET( _xlpm.p,E21, _xlpm.code,IFERROR( IF(AND(LEFT(_xlpm.p,2)="DB",ISNUMBER(SEARCH("-2",_xlpm.p))),"DB-2", IF(LEFT(_xlpm.p,3)="OC-","OC", LEFT(_xlpm.p,_xlfn.XMATCH(TRUE,ISNUMBER(--MID(_xlpm.p,_xlfn.SEQUENCE(LEN(_xlpm.p)),1)))-1) ) ), _xlpm.p ), _xlpm.productType,_xlfn.XLOOKUP(_xlpm.code,'Product Code'!A:A,'Product Code'!D:D,""), IF(OR(RIGHT(_xlpm.p,5)="-Door",RIGHT(_xlpm.p,6)="-DOORS"),_xlpm.productType&" - Door",_xlpm.productType) )} -> x | J21: x | K21: 33 | L21: 34.5 | M21: 24 | N21: =IF(ISNUMBER(SEARCH("Cabinet",F21))=FALSE,"N/A",IF(K21>=24,2,1)) -> 2 | O21: =IF(ISNUMBER(SEARCH("Cabinet",F21))=FALSE,"N/A", IF(ISNUMBER(SEARCH("DB",E21)), IF(ISNUMBER(SEARCH("-2",E21)),2,3), IF(ISNUMBER(SEARCH("-PO",E21)),1, IF(LEFT(E21,1)="B",1,0) ) ) ) -> 3
A22: F9-DB36 | B22: 1620 | C22: =B22*0.3 -> 486 | D22: =C22*1.13 -> 549.18 | E22: =_xlfn.TEXTAFTER(A22,"-") -> DB36 | F22: {=_xlfn.LET( _xlpm.p,E22, _xlpm.code,IFERROR( IF(AND(LEFT(_xlpm.p,2)="DB",ISNUMBER(SEARCH("-2",_xlpm.p))),"DB-2", IF(LEFT(_xlpm.p,3)="OC-","OC", LEFT(_xlpm.p,_xlfn.XMATCH(TRUE,ISNUMBER(--MID(_xlpm.p,_xlfn.SEQUENCE(LEN(_xlpm.p)),1)))-1) ) ), _xlpm.p ), _xlfn.XLOOKUP(_xlpm.code,'Product Code'!A:A,'Product Code'!B:B,"") )} -> Base Cabinet | G22: Drawer | H22: Complete Cabinet | I22: {=_xlfn.LET( _xlpm.p,E22, _xlpm.code,IFERROR( IF(AND(LEFT(_xlpm.p,2)="DB",ISNUMBER(SEARCH("-2",_xlpm.p))),"DB-2", IF(LEFT(_xlpm.p,3)="OC-","OC", LEFT(_xlpm.p,_xlfn.XMATCH(TRUE,ISNUMBER(--MID(_xlpm.p,_xlfn.SEQUENCE(LEN(_xlpm.p)),1)))-1) ) ), _xlpm.p ), _xlpm.productType,_xlfn.XLOOKUP(_xlpm.code,'Product Code'!A:A,'Product Code'!D:D,""), IF(OR(RIGHT(_xlpm.p,5)="-Door",RIGHT(_xlpm.p,6)="-DOORS"),_xlpm.productType&" - Door",_xlpm.productType) )} -> x | J22: x | K22: 36 | L22: 34.5 | M22: 24 | N22: =IF(ISNUMBER(SEARCH("Cabinet",F22))=FALSE,"N/A",IF(K22>=24,2,1)) -> 2 | O22: =IF(ISNUMBER(SEARCH("Cabinet",F22))=FALSE,"N/A", IF(ISNUMBER(SEARCH("DB",E22)), IF(ISNUMBER(SEARCH("-2",E22)),2,3), IF(ISNUMBER(SEARCH("-PO",E22)),1, IF(LEFT(E22,1)="B",1,0) ) ) ) -> 3
A23: F9-FSB33*19.75(10-1/8) | B23: 871 | C23: =B23*0.3 -> 261.3 | D23: =C23*1.13 -> 295.269 | E23: =_xlfn.TEXTAFTER(A23,"-") -> FSB33*19.75(10-1/8) | F23: {=_xlfn.LET( _xlpm.p,E23, _xlpm.code,IFERROR( IF(AND(LEFT(_xlpm.p,2)="DB",ISNUMBER(SEARCH("-2",_xlpm.p))),"DB-2", IF(LEFT(_xlpm.p,3)="OC-","OC", LEFT(_xlpm.p,_xlfn.XMATCH(TRUE,ISNUMBER(--MID(_xlpm.p,_xlfn.SEQUENCE(LEN(_xlpm.p)),1)))-1) ) ), _xlpm.p ), _xlfn.XLOOKUP(_xlpm.code,'Product Code'!A:A,'Product Code'!B:B,"") )} -> Base Cabinet | G23: {=_xlfn.LET( _xlpm.p,E23, _xlpm.code,IFERROR( IF(AND(LEFT(_xlpm.p,2)="DB",ISNUMBER(SEARCH("-2",_xlpm.p))),"DB-2", IF(LEFT(_xlpm.p,3)="OC-","OC", LEFT(_xlpm.p,_xlfn.XMATCH(TRUE,ISNUMBER(--MID(_xlpm.p,_xlfn.SEQUENCE(LEN(_xlpm.p)),1)))-1) ) ), _xlpm.p ), _xlpm.base,_xlfn.XLOOKUP(_xlpm.code,'Product Code'!A:A,'Product Code'!C:C,""), IF(RIGHT(_xlpm.p,3)="-PO",_xlpm.base&" - Pull-Out",_xlpm.base) )} -> Farmhouse Sink | H23: Complete Cabinet | I23: {=_xlfn.LET( _xlpm.p,E23, _xlpm.code,IFERROR( IF(AND(LEFT(_xlpm.p,2)="DB",ISNUMBER(SEARCH("-2",_xlpm.p))),"DB-2", IF(LEFT(_xlpm.p,3)="OC-","OC", LEFT(_xlpm.p,_xlfn.XMATCH(TRUE,ISNUMBER(--MID(_xlpm.p,_xlfn.SEQUENCE(LEN(_xlpm.p)),1)))-1) ) ), _xlpm.p ), _xlpm.productType,_xlfn.XLOOKUP(_xlpm.code,'Product Code'!A:A,'Product Code'!D:D,""), IF(OR(RIGHT(_xlpm.p,5)="-Door",RIGHT(_xlpm.p,6)="-DOORS"),_xlpm.productType&" - Door",_xlpm.productType) )} -> x | J23: x | K23: 33 | L23: 34.5 | M23: 24 | N23: =IF(ISNUMBER(SEARCH("Cabinet",F23))=FALSE,"N/A",IF(K23>=24,2,1)) -> 2 | O23: =IF(ISNUMBER(SEARCH("Cabinet",F23))=FALSE,"N/A", IF(ISNUMBER(SEARCH("DB",E23)), IF(ISNUMBER(SEARCH("-2",E23)),2,3), IF(ISNUMBER(SEARCH("-PO",E23)),1, IF(LEFT(E23,1)="B",1,0) ) ) ) -> 0
A24: F9-FSB36*19.75(10-1/8) | B24: 937 | C24: =B24*0.3 -> 281.1 | D24: =C24*1.13 -> 317.643 | E24: =_xlfn.TEXTAFTER(A24,"-") -> FSB36*19.75(10-1/8) | F24: {=_xlfn.LET( _xlpm.p,E24, _xlpm.code,IFERROR( IF(AND(LEFT(_xlpm.p,2)="DB",ISNUMBER(SEARCH("-2",_xlpm.p))),"DB-2", IF(LEFT(_xlpm.p,3)="OC-","OC", LEFT(_xlpm.p,_xlfn.XMATCH(TRUE,ISNUMBER(--MID(_xlpm.p,_xlfn.SEQUENCE(LEN(_xlpm.p)),1)))-1) ) ), _xlpm.p ), _xlfn.XLOOKUP(_xlpm.code,'Product Code'!A:A,'Product Code'!B:B,"") )} -> Base Cabinet | G24: {=_xlfn.LET( _xlpm.p,E24, _xlpm.code,IFERROR( IF(AND(LEFT(_xlpm.p,2)="DB",ISNUMBER(SEARCH("-2",_xlpm.p))),"DB-2", IF(LEFT(_xlpm.p,3)="OC-","OC", LEFT(_xlpm.p,_xlfn.XMATCH(TRUE,ISNUMBER(--MID(_xlpm.p,_xlfn.SEQUENCE(LEN(_xlpm.p)),1)))-1) ) ), _xlpm.p ), _xlpm.base,_xlfn.XLOOKUP(_xlpm.code,'Product Code'!A:A,'Product Code'!C:C,""), IF(RIGHT(_xlpm.p,3)="-PO",_xlpm.base&" - Pull-Out",_xlpm.base) )} -> Farmhouse Sink | H24: Complete Cabinet | I24: {=_xlfn.LET( _xlpm.p,E24, _xlpm.code,IFERROR( IF(AND(LEFT(_xlpm.p,2)="DB",ISNUMBER(SEARCH("-2",_xlpm.p))),"DB-2", IF(LEFT(_xlpm.p,3)="OC-","OC", LEFT(_xlpm.p,_xlfn.XMATCH(TRUE,ISNUMBER(--MID(_xlpm.p,_xlfn.SEQUENCE(LEN(_xlpm.p)),1)))-1) ) ), _xlpm.p ), _xlpm.productType,_xlfn.XLOOKUP(_xlpm.code,'Product Code'!A:A,'Product Code'!D:D,""), IF(OR(RIGHT(_xlpm.p,5)="-Door",RIGHT(_xlpm.p,6)="-DOORS"),_xlpm.productType&" - Door",_xlpm.productType) )} -> x | J24: x | K24: 36 | L24: 34.5 | M24: 24 | N24: =IF(ISNUMBER(SEARCH("Cabinet",F24))=FALSE,"N/A",IF(K24>=24,2,1)) -> 2 | O24: =IF(ISNUMBER(SEARCH("Cabinet",F24))=FALSE,"N/A", IF(ISNUMBER(SEARCH("DB",E24)), IF(ISNUMBER(SEARCH("-2",E24)),2,3), IF(ISNUMBER(SEARCH("-PO",E24)),1, IF(LEFT(E24,1)="B",1,0) ) ) ) -> 0
A25: F9-LS3309 | B25: 1383 | C25: =B25*0.3 -> 414.9 | D25: =C25*1.13 -> 468.837 | E25: =_xlfn.TEXTAFTER(A25,"-") -> LS3309 | F25: {=_xlfn.LET( _xlpm.p,E25, _xlpm.code,IFERROR( IF(AND(LEFT(_xlpm.p,2)="DB",ISNUMBER(SEARCH("-2",_xlpm.p))),"DB-2", IF(LEFT(_xlpm.p,3)="OC-","OC", LEFT(_xlpm.p,_xlfn.XMATCH(TRUE,ISNUMBER(--MID(_xlpm.p,_xlfn.SEQUENCE(LEN(_xlpm.p)),1)))-1) ) ), _xlpm.p ), _xlfn.XLOOKUP(_xlpm.code,'Product Code'!A:A,'Product Code'!B:B,"") )} -> Base Cabinet | G25: {=_xlfn.LET( _xlpm.p,E25, _xlpm.code,IFERROR( IF(AND(LEFT(_xlpm.p,2)="DB",ISNUMBER(SEARCH("-2",_xlpm.p))),"DB-2", IF(LEFT(_xlpm.p,3)="OC-","OC", LEFT(_xlpm.p,_xlfn.XMATCH(TRUE,ISNUMBER(--MID(_xlpm.p,_xlfn.SEQUENCE(LEN(_xlpm.p)),1)))-1) ) ), _xlpm.p ), _xlpm.base,_xlfn.XLOOKUP(_xlpm.code,'Product Code'!A:A,'Product Code'!C:C,""), IF(RIGHT(_xlpm.p,3)="-PO",_xlpm.base&" - Pull-Out",_xlpm.base) )} -> Corner (90deg) | H25: Complete Cabinet | I25: {=_xlfn.LET( _xlpm.p,E25, _xlpm.code,IFERROR( IF(AND(LEFT(_xlpm.p,2)="DB",ISNUMBER(SEARCH("-2",_xlpm.p))),"DB-2", IF(LEFT(_xlpm.p,3)="OC-","OC", LEFT(_xlpm.p,_xlfn.XMATCH(TRUE,ISNUMBER(--MID(_xlpm.p,_xlfn.SEQUENCE(LEN(_xlpm.p)),1)))-1) ) ), _xlpm.p ), _xlpm.productType,_xlfn.XLOOKUP(_xlpm.code,'Product Code'!A:A,'Product Code'!D:D,""), IF(OR(RIGHT(_xlpm.p,5)="-Door",RIGHT(_xlpm.p,6)="-DOORS"),_xlpm.productType&" - Door",_xlpm.productType) )} -> x | J25: x | K25: 33 | L25: 34.5 | M25: 24 | N25: =IF(ISNUMBER(SEARCH("Cabinet",F25))=FALSE,"N/A",IF(K25>=24,2,1)) -> 2 | O25: =IF(ISNUMBER(SEARCH("Cabinet",F25))=FALSE,"N/A", IF(ISNUMBER(SEARCH("DB",E25)), IF(ISNUMBER(SEARCH("-2",E25)),2,3), IF(ISNUMBER(SEARCH("-PO",E25)),1, IF(LEFT(E25,1)="B",1,0) ) ) ) -> 0
A26: F9-LS3612 | B26: 1478 | C26: =B26*0.3 -> 443.4 | D26: =C26*1.13 -> 501.042 | E26: =_xlfn.TEXTAFTER(A26,"-") -> LS3612 | F26: {=_xlfn.LET( _xlpm.p,E26, _xlpm.code,IFERROR( IF(AND(LEFT(_xlpm.p,2)="DB",ISNUMBER(SEARCH("-2",_xlpm.p))),"DB-2", IF(LEFT(_xlpm.p,3)="OC-","OC", LEFT(_xlpm.p,_xlfn.XMATCH(TRUE,ISNUMBER(--MID(_xlpm.p,_xlfn.SEQUENCE(LEN(_xlpm.p)),1)))-1) ) ), _xlpm.p ), _xlfn.XLOOKUP(_xlpm.code,'Product Code'!A:A,'Product Code'!B:B,"") )} -> Base Cabinet | G26: {=_xlfn.LET( _xlpm.p,E26, _xlpm.code,IFERROR( IF(AND(LEFT(_xlpm.p,2)="DB",ISNUMBER(SEARCH("-2",_xlpm.p))),"DB-2", IF(LEFT(_xlpm.p,3)="OC-","OC", LEFT(_xlpm.p,_xlfn.XMATCH(TRUE,ISNUMBER(--MID(_xlpm.p,_xlfn.SEQUENCE(LEN(_xlpm.p)),1)))-1) ) ), _xlpm.p ), _xlpm.base,_xlfn.XLOOKUP(_xlpm.code,'Product Code'!A:A,'Product Code'!C:C,""), IF(RIGHT(_xlpm.p,3)="-PO",_xlpm.base&" - Pull-Out",_xlpm.base) )} -> Corner (90deg) | H26: Complete Cabinet | I26: {=_xlfn.LET( _xlpm.p,E26, _xlpm.code,IFERROR( IF(AND(LEFT(_xlpm.p,2)="DB",ISNUMBER(SEARCH("-2",_xlpm.p))),"DB-2", IF(LEFT(_xlpm.p,3)="OC-","OC", LEFT(_xlpm.p,_xlfn.XMATCH(TRUE,ISNUMBER(--MID(_xlpm.p,_xlfn.SEQUENCE(LEN(_xlpm.p)),1)))-1) ) ), _xlpm.p ), _xlpm.productType,_xlfn.XLOOKUP(_xlpm.code,'Product Code'!A:A,'Product Code'!D:D,""), IF(OR(RIGHT(_xlpm.p,5)="-Door",RIGHT(_xlpm.p,6)="-DOORS"),_xlpm.productType&" - Door",_xlpm.productType) )} -> x | J26: x | K26: 36 | L26: 34.5 | M26: 24 | N26: 0 | O26: 3
A27: F9-SP06 | B27: 554 | C27: =B27*0.3 -> 166.2 | E27: =_xlfn.TEXTAFTER(A27,"-") -> SP06 | F27: {=_xlfn.LET( _xlpm.p,E27, _xlpm.code,IFERROR( IF(AND(LEFT(_xlpm.p,2)="DB",ISNUMBER(SEARCH("-2",_xlpm.p))),"DB-2", IF(LEFT(_xlpm.p,3)="OC-","OC", LEFT(_xlpm.p,_xlfn.XMATCH(TRUE,ISNUMBER(--MID(_xlpm.p,_xlfn.SEQUENCE(LEN(_xlpm.p)),1)))-1) ) ), _xlpm.p ), _xlfn.XLOOKUP(_xlpm.code,'Product Code'!A:A,'Product Code'!B:B,"") )} -> Base Cabinet | G27: {=_xlfn.LET( _xlpm.p,E27, _xlpm.code,IFERROR( IF(AND(LEFT(_xlpm.p,2)="DB",ISNUMBER(SEARCH("-2",_xlpm.p))),"DB-2", IF(LEFT(_xlpm.p,3)="OC-","OC", LEFT(_xlpm.p,_xlfn.XMATCH(TRUE,ISNUMBER(--MID(_xlpm.p,_xlfn.SEQUENCE(LEN(_xlpm.p)),1)))-1) ) ), _xlpm.p ), _xlpm.base,_xlfn.XLOOKUP(_xlpm.code,'Product Code'!A:A,'Product Code'!C:C,""), IF(RIGHT(_xlpm.p,3)="-PO",_xlpm.base&" - Pull-Out",_xlpm.base) )} -> Spice Rack - Pull-Out | H27: Complete Cabinet | I27: {=_xlfn.LET( _xlpm.p,E27, _xlpm.code,IFERROR( IF(AND(LEFT(_xlpm.p,2)="DB",ISNUMBER(SEARCH("-2",_xlpm.p))),"DB-2", IF(LEFT(_xlpm.p,3)="OC-","OC", LEFT(_xlpm.p,_xlfn.XMATCH(TRUE,ISNUMBER(--MID(_xlpm.p,_xlfn.SEQUENCE(LEN(_xlpm.p)),1)))-1) ) ), _xlpm.p ), _xlpm.productType,_xlfn.XLOOKUP(_xlpm.code,'Product Code'!A:A,'Product Code'!D:D,""), IF(OR(RIGHT(_xlpm.p,5)="-Door",RIGHT(_xlpm.p,6)="-DOORS"),_xlpm.productType&" - Door",_xlpm.productType) )} -> x | J27: x | K27: 6 | L27: 34.5 | M27: 24 | N27: 0 | O27: 3
A28: F9-SP09 | B28: 611 | C28: =B28*0.3 -> 183.3 | D28: =C28*1.13 -> 207.129 | E28: =_xlfn.TEXTAFTER(A28,"-") -> SP09 | F28: {=_xlfn.LET( _xlpm.p,E28, _xlpm.code,IFERROR( IF(AND(LEFT(_xlpm.p,2)="DB",ISNUMBER(SEARCH("-2",_xlpm.p))),"DB-2", IF(LEFT(_xlpm.p,3)="OC-","OC", LEFT(_xlpm.p,_xlfn.XMATCH(TRUE,ISNUMBER(--MID(_xlpm.p,_xlfn.SEQUENCE(LEN(_xlpm.p)),1)))-1) ) ), _xlpm.p ), _xlfn.XLOOKUP(_xlpm.code,'Product Code'!A:A,'Product Code'!B:B,"") )} -> Base Cabinet | G28: {=_xlfn.LET( _xlpm.p,E28, _xlpm.code,IFERROR( IF(AND(LEFT(_xlpm.p,2)="DB",ISNUMBER(SEARCH("-2",_xlpm.p))),"DB-2", IF(LEFT(_xlpm.p,3)="OC-","OC", LEFT(_xlpm.p,_xlfn.XMATCH(TRUE,ISNUMBER(--MID(_xlpm.p,_xlfn.SEQUENCE(LEN(_xlpm.p)),1)))-1) ) ), _xlpm.p ), _xlpm.base,_xlfn.XLOOKUP(_xlpm.code,'Product Code'!A:A,'Product Code'!C:C,""), IF(RIGHT(_xlpm.p,3)="-PO",_xlpm.base&" - Pull-Out",_xlpm.base) )} -> Spice Rack - Pull-Out | H28: Complete Cabinet | I28: {=_xlfn.LET( _xlpm.p,E28, _xlpm.code,IFERROR( IF(AND(LEFT(_xlpm.p,2)="DB",ISNUMBER(SEARCH("-2",_xlpm.p))),"DB-2", IF(LEFT(_xlpm.p,3)="OC-","OC", LEFT(_xlpm.p,_xlfn.XMATCH(TRUE,ISNUMBER(--MID(_xlpm.p,_xlfn.SEQUENCE(LEN(_xlpm.p)),1)))-1) ) ), _xlpm.p ), _xlpm.productType,_xlfn.XLOOKUP(_xlpm.code,'Product Code'!A:A,'Product Code'!D:D,""), IF(OR(RIGHT(_xlpm.p,5)="-Door",RIGHT(_xlpm.p,6)="-DOORS"),_xlpm.productType&" - Door",_xlpm.productType) )} -> x | J28: x | K28: 9 | L28: 34.5 | M28: 24 | N28: 0 | O28: 3
A29: F9-SP12 | B29: 660 | C29: =B29*0.3 -> 198 | D29: =C29*1.13 -> 223.74 | E29: =_xlfn.TEXTAFTER(A29,"-") -> SP12 | F29: {=_xlfn.LET( _xlpm.p,E29, _xlpm.code,IFERROR( IF(AND(LEFT(_xlpm.p,2)="DB",ISNUMBER(SEARCH("-2",_xlpm.p))),"DB-2", IF(LEFT(_xlpm.p,3)="OC-","OC", LEFT(_xlpm.p,_xlfn.XMATCH(TRUE,ISNUMBER(--MID(_xlpm.p,_xlfn.SEQUENCE(LEN(_xlpm.p)),1)))-1) ) ), _xlpm.p ), _xlfn.XLOOKUP(_xlpm.code,'Product Code'!A:A,'Product Code'!B:B,"") )} -> Base Cabinet | G29: {=_xlfn.LET( _xlpm.p,E29, _xlpm.code,IFERROR( IF(AND(LEFT(_xlpm.p,2)="DB",ISNUMBER(SEARCH("-2",_xlpm.p))),"DB-2", IF(LEFT(_xlpm.p,3)="OC-","OC", LEFT(_xlpm.p,_xlfn.XMATCH(TRUE,ISNUMBER(--MID(_xlpm.p,_xlfn.SEQUENCE(LEN(_xlpm.p)),1)))-1) ) ), _xlpm.p ), _xlpm.base,_xlfn.XLOOKUP(_xlpm.code,'Product Code'!A:A,'Product Code'!C:C,""), IF(RIGHT(_xlpm.p,3)="-PO",_xlpm.base&" - Pull-Out",_xlpm.base) )} -> Spice Rack - Pull-Out | H29: Complete Cabinet | I29: {=_xlfn.LET( _xlpm.p,E29, _xlpm.code,IFERROR( IF(AND(LEFT(_xlpm.p,2)="DB",ISNUMBER(SEARCH("-2",_xlpm.p))),"DB-2", IF(LEFT(_xlpm.p,3)="OC-","OC", LEFT(_xlpm.p,_xlfn.XMATCH(TRUE,ISNUMBER(--MID(_xlpm.p,_xlfn.SEQUENCE(LEN(_xlpm.p)),1)))-1) ) ), _xlpm.p ), _xlpm.productType,_xlfn.XLOOKUP(_xlpm.code,'Product Code'!A:A,'Product Code'!D:D,""), IF(OR(RIGHT(_xlpm.p,5)="-Door",RIGHT(_xlpm.p,6)="-DOORS"),_xlpm.productType&" - Door",_xlpm.productType) )} -> x | J29: x | K29: 12 | L29: 34.5 | M29: 24 | N29: 0 | O29: 3
A30: F9-BMC27 | B30: 1241 | C30: =B30*0.3 -> 372.3 | E30: =_xlfn.TEXTAFTER(A30,"-") -> BMC27 | F30: {=_xlfn.LET( _xlpm.p,E30, _xlpm.code,IFERROR( IF(AND(LEFT(_xlpm.p,2)="DB",ISNUMBER(SEARCH("-2",_xlpm.p))),"DB-2", IF(LEFT(_xlpm.p,3)="OC-","OC", LEFT(_xlpm.p,_xlfn.XMATCH(TRUE,ISNUMBER(--MID(_xlpm.p,_xlfn.SEQUENCE(LEN(_xlpm.p)),1)))-1) ) ), _xlpm.p ), _xlfn.XLOOKUP(_xlpm.code,'Product Code'!A:A,'Product Code'!B:B,"") )} -> Base Microwave Cabinet | G30: {=_xlfn.LET( _xlpm.p,E30, _xlpm.code,IFERROR( IF(AND(LEFT(_xlpm.p,2)="DB",ISNUMBER(SEARCH("-2",_xlpm.p))),"DB-2", IF(LEFT(_xlpm.p,3)="OC-","OC", LEFT(_xlpm.p,_xlfn.XMATCH(TRUE,ISNUMBER(--MID(_xlpm.p,_xlfn.SEQUENCE(LEN(_xlpm.p)),1)))-1) ) ), _xlpm.p ), _xlpm.base,_xlfn.XLOOKUP(_xlpm.code,'Product Code'!A:A,'Product Code'!C:C,""), IF(RIGHT(_xlpm.p,3)="-PO",_xlpm.base&" - Pull-Out",_xlpm.base) )} -> 0 | I30: {=_xlfn.LET( _xlpm.p,E30, _xlpm.code,IFERROR( IF(AND(LEFT(_xlpm.p,2)="DB",ISNUMBER(SEARCH("-2",_xlpm.p))),"DB-2", IF(LEFT(_xlpm.p,3)="OC-","OC", LEFT(_xlpm.p,_xlfn.XMATCH(TRUE,ISNUMBER(--MID(_xlpm.p,_xlfn.SEQUENCE(LEN(_xlpm.p)),1)))-1) ) ), _xlpm.p ), _xlpm.productType,_xlfn.XLOOKUP(_xlpm.code,'Product Code'!A:A,'Product Code'!D:D,""), IF(OR(RIGHT(_xlpm.p,5)="-Door",RIGHT(_xlpm.p,6)="-DOORS"),_xlpm.productType&" - Door",_xlpm.productType) )} -> - | N30: 0 | O30: 3
A31: F9-FB09 | B31: 492 | C31: =B31*0.3 -> 147.6 | E31: =_xlfn.TEXTAFTER(A31,"-") -> FB09 | F31: {=_xlfn.LET( _xlpm.p,E31, _xlpm.code,IFERROR( IF(AND(LEFT(_xlpm.p,2)="DB",ISNUMBER(SEARCH("-2",_xlpm.p))),"DB-2", IF(LEFT(_xlpm.p,3)="OC-","OC", LEFT(_xlpm.p,_xlfn.XMATCH(TRUE,ISNUMBER(--MID(_xlpm.p,_xlfn.SEQUENCE(LEN(_xlpm.p)),1)))-1) ) ), _xlpm.p ), _xlfn.XLOOKUP(_xlpm.code,'Product Code'!A:A,'Product Code'!B:B,"") )} -> Bathroom - Base Cabinet | G31: {=_xlfn.LET( _xlpm.p,E31, _xlpm.code,IFERROR( IF(AND(LEFT(_xlpm.p,2)="DB",ISNUMBER(SEARCH("-2",_xlpm.p))),"DB-2", IF(LEFT(_xlpm.p,3)="OC-","OC", LEFT(_xlpm.p,_xlfn.XMATCH(TRUE,ISNUMBER(--MID(_xlpm.p,_xlfn.SEQUENCE(LEN(_xlpm.p)),1)))-1) ) ), _xlpm.p ), _xlpm.base,_xlfn.XLOOKUP(_xlpm.code,'Product Code'!A:A,'Product Code'!C:C,""), IF(RIGHT(_xlpm.p,3)="-PO",_xlpm.base&" - Pull-Out",_xlpm.base) )} -> 0 | I31: {=_xlfn.LET( _xlpm.p,E31, _xlpm.code,IFERROR( IF(AND(LEFT(_xlpm.p,2)="DB",ISNUMBER(SEARCH("-2",_xlpm.p))),"DB-2", IF(LEFT(_xlpm.p,3)="OC-","OC", LEFT(_xlpm.p,_xlfn.XMATCH(TRUE,ISNUMBER(--MID(_xlpm.p,_xlfn.SEQUENCE(LEN(_xlpm.p)),1)))-1) ) ), _xlpm.p ), _xlpm.productType,_xlfn.XLOOKUP(_xlpm.code,'Product Code'!A:A,'Product Code'!D:D,""), IF(OR(RIGHT(_xlpm.p,5)="-Door",RIGHT(_xlpm.p,6)="-DOORS"),_xlpm.productType&" - Door",_xlpm.productType) )} -> - | N31: 0 | O31: 3
A32: F9-FB12 | B32: 545 | C32: =B32*0.3 -> 163.5 | E32: =_xlfn.TEXTAFTER(A32,"-") -> FB12 | F32: {=_xlfn.LET( _xlpm.p,E32, _xlpm.code,IFERROR( IF(AND(LEFT(_xlpm.p,2)="DB",ISNUMBER(SEARCH("-2",_xlpm.p))),"DB-2", IF(LEFT(_xlpm.p,3)="OC-","OC", LEFT(_xlpm.p,_xlfn.XMATCH(TRUE,ISNUMBER(--MID(_xlpm.p,_xlfn.SEQUENCE(LEN(_xlpm.p)),1)))-1) ) ), _xlpm.p ), _xlfn.XLOOKUP(_xlpm.code,'Product Code'!A:A,'Product Code'!B:B,"") )} -> Bathroom - Base Cabinet | G32: {=_xlfn.LET( _xlpm.p,E32, _xlpm.code,IFERROR( IF(AND(LEFT(_xlpm.p,2)="DB",ISNUMBER(SEARCH("-2",_xlpm.p))),"DB-2", IF(LEFT(_xlpm.p,3)="OC-","OC", LEFT(_xlpm.p,_xlfn.XMATCH(TRUE,ISNUMBER(--MID(_xlpm.p,_xlfn.SEQUENCE(LEN(_xlpm.p)),1)))-1) ) ), _xlpm.p ), _xlpm.base,_xlfn.XLOOKUP(_xlpm.code,'Product Code'!A:A,'Product Code'!C:C,""), IF(RIGHT(_xlpm.p,3)="-PO",_xlpm.base&" - Pull-Out",_xlpm.base) )} -> 0 | I32: {=_xlfn.LET( _xlpm.p,E32, _xlpm.code,IFERROR( IF(AND(LEFT(_xlpm.p,2)="DB",ISNUMBER(SEARCH("-2",_xlpm.p))),"DB-2", IF(LEFT(_xlpm.p,3)="OC-","OC", LEFT(_xlpm.p,_xlfn.XMATCH(TRUE,ISNUMBER(--MID(_xlpm.p,_xlfn.SEQUENCE(LEN(_xlpm.p)),1)))-1) ) ), _xlpm.p ), _xlpm.productType,_xlfn.XLOOKUP(_xlpm.code,'Product Code'!A:A,'Product Code'!D:D,""), IF(OR(RIGHT(_xlpm.p,5)="-Door",RIGHT(_xlpm.p,6)="-DOORS"),_xlpm.productType&" - Door",_xlpm.productType) )} -> - | N32: 0 | O32: 2
A33: F9-FB15 | B33: 616 | C33: =B33*0.3 -> 184.8 | E33: =_xlfn.TEXTAFTER(A33,"-") -> FB15 | F33: {=_xlfn.LET( _xlpm.p,E33, _xlpm.code,IFERROR( IF(AND(LEFT(_xlpm.p,2)="DB",ISNUMBER(SEARCH("-2",_xlpm.p))),"DB-2", IF(LEFT(_xlpm.p,3)="OC-","OC", LEFT(_xlpm.p,_xlfn.XMATCH(TRUE,ISNUMBER(--MID(_xlpm.p,_xlfn.SEQUENCE(LEN(_xlpm.p)),1)))-1) ) ), _xlpm.p ), _xlfn.XLOOKUP(_xlpm.code,'Product Code'!A:A,'Product Code'!B:B,"") )} -> Bathroom - Base Cabinet | G33: {=_xlfn.LET( _xlpm.p,E33, _xlpm.code,IFERROR( IF(AND(LEFT(_xlpm.p,2)="DB",ISNUMBER(SEARCH("-2",_xlpm.p))),"DB-2", IF(LEFT(_xlpm.p,3)="OC-","OC", LEFT(_xlpm.p,_xlfn.XMATCH(TRUE,ISNUMBER(--MID(_xlpm.p,_xlfn.SEQUENCE(LEN(_xlpm.p)),1)))-1) ) ), _xlpm.p ), _xlpm.base,_xlfn.XLOOKUP(_xlpm.code,'Product Code'!A:A,'Product Code'!C:C,""), IF(RIGHT(_xlpm.p,3)="-PO",_xlpm.base&" - Pull-Out",_xlpm.base) )} -> 0 | I33: {=_xlfn.LET( _xlpm.p,E33, _xlpm.code,IFERROR( IF(AND(LEFT(_xlpm.p,2)="DB",ISNUMBER(SEARCH("-2",_xlpm.p))),"DB-2", IF(LEFT(_xlpm.p,3)="OC-","OC", LEFT(_xlpm.p,_xlfn.XMATCH(TRUE,ISNUMBER(--MID(_xlpm.p,_xlfn.SEQUENCE(LEN(_xlpm.p)),1)))-1) ) ), _xlpm.p ), _xlpm.productType,_xlfn.XLOOKUP(_xlpm.code,'Product Code'!A:A,'Product Code'!D:D,""), IF(OR(RIGHT(_xlpm.p,5)="-Door",RIGHT(_xlpm.p,6)="-DOORS"),_xlpm.productType&" - Door",_xlpm.productType) )} -> - | N33: 0 | O33: 3
A34: F9-FB18 | B34: 670 | C34: =B34*0.3 -> 201 | E34: =_xlfn.TEXTAFTER(A34,"-") -> FB18 | F34: {=_xlfn.LET( _xlpm.p,E34, _xlpm.code,IFERROR( IF(AND(LEFT(_xlpm.p,2)="DB",ISNUMBER(SEARCH("-2",_xlpm.p))),"DB-2", IF(LEFT(_xlpm.p,3)="OC-","OC", LEFT(_xlpm.p,_xlfn.XMATCH(TRUE,ISNUMBER(--MID(_xlpm.p,_xlfn.SEQUENCE(LEN(_xlpm.p)),1)))-1) ) ), _xlpm.p ), _xlfn.XLOOKUP(_xlpm.code,'Product Code'!A:A,'Product Code'!B:B,"") )} -> Bathroom - Base Cabinet | G34: {=_xlfn.LET( _xlpm.p,E34, _xlpm.code,IFERROR( IF(AND(LEFT(_xlpm.p,2)="DB",ISNUMBER(SEARCH("-2",_xlpm.p))),"DB-2", IF(LEFT(_xlpm.p,3)="OC-","OC", LEFT(_xlpm.p,_xlfn.XMATCH(TRUE,ISNUMBER(--MID(_xlpm.p,_xlfn.SEQUENCE(LEN(_xlpm.p)),1)))-1) ) ), _xlpm.p ), _xlpm.base,_xlfn.XLOOKUP(_xlpm.code,'Product Code'!A:A,'Product Code'!C:C,""), IF(RIGHT(_xlpm.p,3)="-PO",_xlpm.base&" - Pull-Out",_xlpm.base) )} -> 0 | I34: {=_xlfn.LET( _xlpm.p,E34, _xlpm.code,IFERROR( IF(AND(LEFT(_xlpm.p,2)="DB",ISNUMBER(SEARCH("-2",_xlpm.p))),"DB-2", IF(LEFT(_xlpm.p,3)="OC-","OC", LEFT(_xlpm.p,_xlfn.XMATCH(TRUE,ISNUMBER(--MID(_xlpm.p,_xlfn.SEQUENCE(LEN(_xlpm.p)),1)))-1) ) ), _xlpm.p ), _xlpm.productType,_xlfn.XLOOKUP(_xlpm.code,'Product Code'!A:A,'Product Code'!D:D,""), IF(OR(RIGHT(_xlpm.p,5)="-Door",RIGHT(_xlpm.p,6)="-DOORS"),_xlpm.productType&" - Door",_xlpm.productType) )} -> - | N34: 0 | O34: 2
A35: F9-FB21 | B35: 732 | C35: =B35*0.3 -> 219.6 | E35: =_xlfn.TEXTAFTER(A35,"-") -> FB21 | F35: {=_xlfn.LET( _xlpm.p,E35, _xlpm.code,IFERROR( IF(AND(LEFT(_xlpm.p,2)="DB",ISNUMBER(SEARCH("-2",_xlpm.p))),"DB-2", IF(LEFT(_xlpm.p,3)="OC-","OC", LEFT(_xlpm.p,_xlfn.XMATCH(TRUE,ISNUMBER(--MID(_xlpm.p,_xlfn.SEQUENCE(LEN(_xlpm.p)),1)))-1) ) ), _xlpm.p ), _xlfn.XLOOKUP(_xlpm.code,'Product Code'!A:A,'Product Code'!B:B,"") )} -> Bathroom - Base Cabinet | G35: {=_xlfn.LET( _xlpm.p,E35, _xlpm.code,IFERROR( IF(AND(LEFT(_xlpm.p,2)="DB",ISNUMBER(SEARCH("-2",_xlpm.p))),"DB-2", IF(LEFT(_xlpm.p,3)="OC-","OC", LEFT(_xlpm.p,_xlfn.XMATCH(TRUE,ISNUMBER(--MID(_xlpm.p,_xlfn.SEQUENCE(LEN(_xlpm.p)),1)))-1) ) ), _xlpm.p ), _xlpm.base,_xlfn.XLOOKUP(_xlpm.code,'Product Code'!A:A,'Product Code'!C:C,""), IF(RIGHT(_xlpm.p,3)="-PO",_xlpm.base&" - Pull-Out",_xlpm.base) )} -> 0 | I35: {=_xlfn.LET( _xlpm.p,E35, _xlpm.code,IFERROR( IF(AND(LEFT(_xlpm.p,2)="DB",ISNUMBER(SEARCH("-2",_xlpm.p))),"DB-2", IF(LEFT(_xlpm.p,3)="OC-","OC", LEFT(_xlpm.p,_xlfn.XMATCH(TRUE,ISNUMBER(--MID(_xlpm.p,_xlfn.SEQUENCE(LEN(_xlpm.p)),1)))-1) ) ), _xlpm.p ), _xlpm.productType,_xlfn.XLOOKUP(_xlpm.code,'Product Code'!A:A,'Product Code'!D:D,""), IF(OR(RIGHT(_xlpm.p,5)="-Door",RIGHT(_xlpm.p,6)="-DOORS"),_xlpm.productType&" - Door",_xlpm.productType) )} -> - | N35: 0 | O35: 3
A36: F9-FB24 | B36: 817 | C36: =B36*0.3 -> 245.1 | E36: =_xlfn.TEXTAFTER(A36,"-") -> FB24 | F36: {=_xlfn.LET( _xlpm.p,E36, _xlpm.code,IFERROR( IF(AND(LEFT(_xlpm.p,2)="DB",ISNUMBER(SEARCH("-2",_xlpm.p))),"DB-2", IF(LEFT(_xlpm.p,3)="OC-","OC", LEFT(_xlpm.p,_xlfn.XMATCH(TRUE,ISNUMBER(--MID(_xlpm.p,_xlfn.SEQUENCE(LEN(_xlpm.p)),1)))-1) ) ), _xlpm.p ), _xlfn.XLOOKUP(_xlpm.code,'Product Code'!A:A,'Product Code'!B:B,"") )} -> Bathroom - Base Cabinet | G36: {=_xlfn.LET( _xlpm.p,E36, _xlpm.code,IFERROR( IF(AND(LEFT(_xlpm.p,2)="DB",ISNUMBER(SEARCH("-2",_xlpm.p))),"DB-2", IF(LEFT(_xlpm.p,3)="OC-","OC", LEFT(_xlpm.p,_xlfn.XMATCH(TRUE,ISNUMBER(--MID(_xlpm.p,_xlfn.SEQUENCE(LEN(_xlpm.p)),1)))-1) ) ), _xlpm.p ), _xlpm.base,_xlfn.XLOOKUP(_xlpm.code,'Product Code'!A:A,'Product Code'!C:C,""), IF(RIGHT(_xlpm.p,3)="-PO",_xlpm.base&" - Pull-Out",_xlpm.base) )} -> 0 | I36: {=_xlfn.LET( _xlpm.p,E36, _xlpm.code,IFERROR( IF(AND(LEFT(_xlpm.p,2)="DB",ISNUMBER(SEARCH("-2",_xlpm.p))),"DB-2", IF(LEFT(_xlpm.p,3)="OC-","OC", LEFT(_xlpm.p,_xlfn.XMATCH(TRUE,ISNUMBER(--MID(_xlpm.p,_xlfn.SEQUENCE(LEN(_xlpm.p)),1)))-1) ) ), _xlpm.p ), _xlpm.productType,_xlfn.XLOOKUP(_xlpm.code,'Product Code'!A:A,'Product Code'!D:D,""), IF(OR(RIGHT(_xlpm.p,5)="-Door",RIGHT(_xlpm.p,6)="-DOORS"),_xlpm.productType&" - Door",_xlpm.productType) )} -> - | N36: 0 | O36: 3
